<?xml version="1.0" encoding="UTF-8"?>
<!-- Generated by org.testng.reporters.JUnitReportReporter -->
<testsuite hostname="KoBietLun" failures="3" tests="35" name="DAO_Test.HoaDonChiTietDAO_Test" time="4.325" errors="17" timestamp="2024-04-12T15:07:29 ICT" skipped="0">
  <testcase classname="DAO_Test.HoaDonChiTietDAO_Test" name="TestSelect_getTHONGTIN_KHACHHANG_NHANVIEN_Pass" time="0.037"/>
  <system-out/>
  <testcase classname="DAO_Test.HoaDonChiTietDAO_Test" name="TestSelect_getDanhSachSanPham_HoaDonChiTiet_Pass" time="0.136"/>
  <system-out/>
  <testcase classname="DAO_Test.HoaDonChiTietDAO_Test" name="TestSelect_getDanhSachSanPham_HoaDonChiTiet_Fail" time="0.068">
    <error message="
Expected exception of type class com.microsoft.sqlserver.jdbc.SQLServerException but got java.lang.AssertionError: expected [null] but found [[]]" type="org.testng.TestException">
      <![CDATA[org.testng.TestException: 
Expected exception of type class com.microsoft.sqlserver.jdbc.SQLServerException but got java.lang.AssertionError: expected [null] but found [[]]
at org.testng.internal.ExpectedExceptionsHolder.wrongException(ExpectedExceptionsHolder.java:68)
at org.testng.internal.TestInvoker.considerExceptions(TestInvoker.java:739)
at org.testng.internal.TestInvoker.invokeMethod(TestInvoker.java:634)
at org.testng.internal.TestInvoker.invokeTestMethod(TestInvoker.java:173)
at org.testng.internal.MethodRunner.runInSequence(MethodRunner.java:46)
at org.testng.internal.TestInvoker$MethodInvocationAgent.invoke(TestInvoker.java:824)
at org.testng.internal.TestInvoker.invokeTestMethods(TestInvoker.java:146)
at org.testng.internal.TestMethodWorker.invokeTestMethods(TestMethodWorker.java:146)
at org.testng.internal.TestMethodWorker.run(TestMethodWorker.java:128)
at java.base/java.util.ArrayList.forEach(ArrayList.java:1511)
at org.testng.TestRunner.privateRun(TestRunner.java:794)
at org.testng.TestRunner.run(TestRunner.java:596)
at org.testng.SuiteRunner.runTest(SuiteRunner.java:377)
at org.testng.SuiteRunner.runSequentially(SuiteRunner.java:371)
at org.testng.SuiteRunner.privateRun(SuiteRunner.java:332)
at org.testng.SuiteRunner.run(SuiteRunner.java:276)
at org.testng.SuiteRunnerWorker.runSuite(SuiteRunnerWorker.java:53)
at org.testng.SuiteRunnerWorker.run(SuiteRunnerWorker.java:96)
at org.testng.TestNG.runSuitesSequentially(TestNG.java:1212)
at org.testng.TestNG.runSuitesLocally(TestNG.java:1134)
at org.testng.TestNG.runSuites(TestNG.java:1063)
at org.testng.TestNG.run(TestNG.java:1031)
at org.testng.remote.AbstractRemoteTestNG.run(AbstractRemoteTestNG.java:115)
at org.testng.remote.RemoteTestNG.initAndRun(RemoteTestNG.java:251)
at org.testng.remote.RemoteTestNG.main(RemoteTestNG.java:77)
Caused by: java.lang.AssertionError: expected [null] but found [[]]
at org.testng.Assert.fail(Assert.java:99)
at org.testng.Assert.failNotSame(Assert.java:1033)
at org.testng.Assert.assertNull(Assert.java:965)
at org.testng.Assert.assertNull(Assert.java:953)
at DAO_Test.HoaDonChiTietDAO_Test.TestSelect_getDanhSachSanPham_HoaDonChiTiet_Fail(HoaDonChiTietDAO_Test.java:319)
at java.base/jdk.internal.reflect.DirectMethodHandleAccessor.invoke(DirectMethodHandleAccessor.java:104)
at java.base/java.lang.reflect.Method.invoke(Method.java:578)
at org.testng.internal.MethodInvocationHelper.invokeMethod(MethodInvocationHelper.java:133)
at org.testng.internal.TestInvoker.invokeMethod(TestInvoker.java:598)
... 22 more
]]>
    </error>
  </testcase> <!-- TestSelect_getDanhSachSanPham_HoaDonChiTiet_Fail -->
  <system-out/>
  <testcase classname="DAO_Test.HoaDonChiTietDAO_Test" name="TestSelecte_ByID_Fail" time="0.026">
    <error message="
Method HoaDonChiTietDAO_Test.TestSelecte_ByID_Fail()[pri:0, instance:DAO_Test.HoaDonChiTietDAO_Test@68e5eea7] should have thrown an exception of type class com.microsoft.sqlserver.jdbc.SQLServerException" type="org.testng.TestException">
      <![CDATA[org.testng.TestException: 
Method HoaDonChiTietDAO_Test.TestSelecte_ByID_Fail()[pri:0, instance:DAO_Test.HoaDonChiTietDAO_Test@68e5eea7] should have thrown an exception of type class com.microsoft.sqlserver.jdbc.SQLServerException
at org.testng.internal.ExpectedExceptionsHolder.noException(ExpectedExceptionsHolder.java:82)
at org.testng.internal.TestInvoker.considerExceptions(TestInvoker.java:749)
at org.testng.internal.TestInvoker.invokeMethod(TestInvoker.java:634)
at org.testng.internal.TestInvoker.invokeTestMethod(TestInvoker.java:173)
at org.testng.internal.MethodRunner.runInSequence(MethodRunner.java:46)
at org.testng.internal.TestInvoker$MethodInvocationAgent.invoke(TestInvoker.java:824)
at org.testng.internal.TestInvoker.invokeTestMethods(TestInvoker.java:146)
at org.testng.internal.TestMethodWorker.invokeTestMethods(TestMethodWorker.java:146)
at org.testng.internal.TestMethodWorker.run(TestMethodWorker.java:128)
at java.base/java.util.ArrayList.forEach(ArrayList.java:1511)
at org.testng.TestRunner.privateRun(TestRunner.java:794)
at org.testng.TestRunner.run(TestRunner.java:596)
at org.testng.SuiteRunner.runTest(SuiteRunner.java:377)
at org.testng.SuiteRunner.runSequentially(SuiteRunner.java:371)
at org.testng.SuiteRunner.privateRun(SuiteRunner.java:332)
at org.testng.SuiteRunner.run(SuiteRunner.java:276)
at org.testng.SuiteRunnerWorker.runSuite(SuiteRunnerWorker.java:53)
at org.testng.SuiteRunnerWorker.run(SuiteRunnerWorker.java:96)
at org.testng.TestNG.runSuitesSequentially(TestNG.java:1212)
at org.testng.TestNG.runSuitesLocally(TestNG.java:1134)
at org.testng.TestNG.runSuites(TestNG.java:1063)
at org.testng.TestNG.run(TestNG.java:1031)
at org.testng.remote.AbstractRemoteTestNG.run(AbstractRemoteTestNG.java:115)
at org.testng.remote.RemoteTestNG.initAndRun(RemoteTestNG.java:251)
at org.testng.remote.RemoteTestNG.main(RemoteTestNG.java:77)
]]>
    </error>
  </testcase> <!-- TestSelecte_ByID_Fail -->
  <system-out/>
  <testcase classname="DAO_Test.HoaDonChiTietDAO_Test" name="TestInsert_All_Pass" time="0.150"/>
  <system-out/>
  <testcase classname="DAO_Test.HoaDonChiTietDAO_Test" name="TestUpdate_MaSP_Fail" time="0.053">
    <error message="
Method HoaDonChiTietDAO_Test.TestUpdate_MaSP_Fail()[pri:0, instance:DAO_Test.HoaDonChiTietDAO_Test@68e5eea7] should have thrown an exception of type class com.microsoft.sqlserver.jdbc.SQLServerException" type="org.testng.TestException">
      <![CDATA[org.testng.TestException: 
Method HoaDonChiTietDAO_Test.TestUpdate_MaSP_Fail()[pri:0, instance:DAO_Test.HoaDonChiTietDAO_Test@68e5eea7] should have thrown an exception of type class com.microsoft.sqlserver.jdbc.SQLServerException
at org.testng.internal.ExpectedExceptionsHolder.noException(ExpectedExceptionsHolder.java:82)
at org.testng.internal.TestInvoker.considerExceptions(TestInvoker.java:749)
at org.testng.internal.TestInvoker.invokeMethod(TestInvoker.java:634)
at org.testng.internal.TestInvoker.invokeTestMethod(TestInvoker.java:173)
at org.testng.internal.MethodRunner.runInSequence(MethodRunner.java:46)
at org.testng.internal.TestInvoker$MethodInvocationAgent.invoke(TestInvoker.java:824)
at org.testng.internal.TestInvoker.invokeTestMethods(TestInvoker.java:146)
at org.testng.internal.TestMethodWorker.invokeTestMethods(TestMethodWorker.java:146)
at org.testng.internal.TestMethodWorker.run(TestMethodWorker.java:128)
at java.base/java.util.ArrayList.forEach(ArrayList.java:1511)
at org.testng.TestRunner.privateRun(TestRunner.java:794)
at org.testng.TestRunner.run(TestRunner.java:596)
at org.testng.SuiteRunner.runTest(SuiteRunner.java:377)
at org.testng.SuiteRunner.runSequentially(SuiteRunner.java:371)
at org.testng.SuiteRunner.privateRun(SuiteRunner.java:332)
at org.testng.SuiteRunner.run(SuiteRunner.java:276)
at org.testng.SuiteRunnerWorker.runSuite(SuiteRunnerWorker.java:53)
at org.testng.SuiteRunnerWorker.run(SuiteRunnerWorker.java:96)
at org.testng.TestNG.runSuitesSequentially(TestNG.java:1212)
at org.testng.TestNG.runSuitesLocally(TestNG.java:1134)
at org.testng.TestNG.runSuites(TestNG.java:1063)
at org.testng.TestNG.run(TestNG.java:1031)
at org.testng.remote.AbstractRemoteTestNG.run(AbstractRemoteTestNG.java:115)
at org.testng.remote.RemoteTestNG.initAndRun(RemoteTestNG.java:251)
at org.testng.remote.RemoteTestNG.main(RemoteTestNG.java:77)
]]>
    </error>
  </testcase> <!-- TestUpdate_MaSP_Fail -->
  <system-out/>
  <testcase classname="DAO_Test.HoaDonChiTietDAO_Test" name="TestSelecte_All_Pass" time="0.028"/>
  <system-out/>
  <testcase classname="DAO_Test.HoaDonChiTietDAO_Test" name="TestSelect_delete_mahd_Fail" time="0.084">
    <error message="
Expected exception of type class com.microsoft.sqlserver.jdbc.SQLServerException but got java.lang.AssertionError: expected object to not be null" type="org.testng.TestException">
      <![CDATA[org.testng.TestException: 
Expected exception of type class com.microsoft.sqlserver.jdbc.SQLServerException but got java.lang.AssertionError: expected object to not be null
at org.testng.internal.ExpectedExceptionsHolder.wrongException(ExpectedExceptionsHolder.java:68)
at org.testng.internal.TestInvoker.considerExceptions(TestInvoker.java:739)
at org.testng.internal.TestInvoker.invokeMethod(TestInvoker.java:634)
at org.testng.internal.TestInvoker.invokeTestMethod(TestInvoker.java:173)
at org.testng.internal.MethodRunner.runInSequence(MethodRunner.java:46)
at org.testng.internal.TestInvoker$MethodInvocationAgent.invoke(TestInvoker.java:824)
at org.testng.internal.TestInvoker.invokeTestMethods(TestInvoker.java:146)
at org.testng.internal.TestMethodWorker.invokeTestMethods(TestMethodWorker.java:146)
at org.testng.internal.TestMethodWorker.run(TestMethodWorker.java:128)
at java.base/java.util.ArrayList.forEach(ArrayList.java:1511)
at org.testng.TestRunner.privateRun(TestRunner.java:794)
at org.testng.TestRunner.run(TestRunner.java:596)
at org.testng.SuiteRunner.runTest(SuiteRunner.java:377)
at org.testng.SuiteRunner.runSequentially(SuiteRunner.java:371)
at org.testng.SuiteRunner.privateRun(SuiteRunner.java:332)
at org.testng.SuiteRunner.run(SuiteRunner.java:276)
at org.testng.SuiteRunnerWorker.runSuite(SuiteRunnerWorker.java:53)
at org.testng.SuiteRunnerWorker.run(SuiteRunnerWorker.java:96)
at org.testng.TestNG.runSuitesSequentially(TestNG.java:1212)
at org.testng.TestNG.runSuitesLocally(TestNG.java:1134)
at org.testng.TestNG.runSuites(TestNG.java:1063)
at org.testng.TestNG.run(TestNG.java:1031)
at org.testng.remote.AbstractRemoteTestNG.run(AbstractRemoteTestNG.java:115)
at org.testng.remote.RemoteTestNG.initAndRun(RemoteTestNG.java:251)
at org.testng.remote.RemoteTestNG.main(RemoteTestNG.java:77)
Caused by: java.lang.AssertionError: expected object to not be null
at org.testng.Assert.fail(Assert.java:99)
at org.testng.Assert.assertNotNull(Assert.java:942)
at org.testng.Assert.assertNotNull(Assert.java:926)
at DAO_Test.HoaDonChiTietDAO_Test.TestSelect_delete_mahd_Fail(HoaDonChiTietDAO_Test.java:418)
at java.base/jdk.internal.reflect.DirectMethodHandleAccessor.invoke(DirectMethodHandleAccessor.java:104)
at java.base/java.lang.reflect.Method.invoke(Method.java:578)
at org.testng.internal.MethodInvocationHelper.invokeMethod(MethodInvocationHelper.java:133)
at org.testng.internal.TestInvoker.invokeMethod(TestInvoker.java:598)
... 22 more
]]>
    </error>
  </testcase> <!-- TestSelect_delete_mahd_Fail -->
  <system-out/>
  <testcase classname="DAO_Test.HoaDonChiTietDAO_Test" name="TestSelect_getThanhToan_Pass" time="0.128"/>
  <system-out/>
  <testcase classname="DAO_Test.HoaDonChiTietDAO_Test" name="TestSelect_selectby_MaHD_MASP_Pass" time="0.083">
    <failure message="expected object to not be null" type="java.lang.AssertionError">
      <![CDATA[java.lang.AssertionError: expected object to not be null
at org.testng.Assert.fail(Assert.java:99)
at org.testng.Assert.assertNotNull(Assert.java:942)
at org.testng.Assert.assertNotNull(Assert.java:926)
at DAO_Test.HoaDonChiTietDAO_Test.TestSelect_selectby_MaHD_MASP_Pass(HoaDonChiTietDAO_Test.java:389)
at java.base/jdk.internal.reflect.DirectMethodHandleAccessor.invoke(DirectMethodHandleAccessor.java:104)
at java.base/java.lang.reflect.Method.invoke(Method.java:578)
at org.testng.internal.MethodInvocationHelper.invokeMethod(MethodInvocationHelper.java:133)
at org.testng.internal.TestInvoker.invokeMethod(TestInvoker.java:598)
at org.testng.internal.TestInvoker.invokeTestMethod(TestInvoker.java:173)
at org.testng.internal.MethodRunner.runInSequence(MethodRunner.java:46)
at org.testng.internal.TestInvoker$MethodInvocationAgent.invoke(TestInvoker.java:824)
at org.testng.internal.TestInvoker.invokeTestMethods(TestInvoker.java:146)
at org.testng.internal.TestMethodWorker.invokeTestMethods(TestMethodWorker.java:146)
at org.testng.internal.TestMethodWorker.run(TestMethodWorker.java:128)
at java.base/java.util.ArrayList.forEach(ArrayList.java:1511)
at org.testng.TestRunner.privateRun(TestRunner.java:794)
at org.testng.TestRunner.run(TestRunner.java:596)
at org.testng.SuiteRunner.runTest(SuiteRunner.java:377)
at org.testng.SuiteRunner.runSequentially(SuiteRunner.java:371)
at org.testng.SuiteRunner.privateRun(SuiteRunner.java:332)
at org.testng.SuiteRunner.run(SuiteRunner.java:276)
at org.testng.SuiteRunnerWorker.runSuite(SuiteRunnerWorker.java:53)
at org.testng.SuiteRunnerWorker.run(SuiteRunnerWorker.java:96)
at org.testng.TestNG.runSuitesSequentially(TestNG.java:1212)
at org.testng.TestNG.runSuitesLocally(TestNG.java:1134)
at org.testng.TestNG.runSuites(TestNG.java:1063)
at org.testng.TestNG.run(TestNG.java:1031)
at org.testng.remote.AbstractRemoteTestNG.run(AbstractRemoteTestNG.java:115)
at org.testng.remote.RemoteTestNG.initAndRun(RemoteTestNG.java:251)
at org.testng.remote.RemoteTestNG.main(RemoteTestNG.java:77)
]]>
    </failure>
  </testcase> <!-- TestSelect_selectby_MaHD_MASP_Pass -->
  <system-out/>
  <testcase classname="DAO_Test.HoaDonChiTietDAO_Test" name="TestSelect_delete_mahd_Pass" time="0.077"/>
  <system-out/>
  <testcase classname="DAO_Test.HoaDonChiTietDAO_Test" name="TestUpdate_GhiChu_Pass" time="0.041"/>
  <system-out/>
  <testcase classname="DAO_Test.HoaDonChiTietDAO_Test" name="TestInsert_NullMaSP_Fail" time="0.064">
    <error message="
Method HoaDonChiTietDAO_Test.TestInsert_NullMaSP_Fail()[pri:0, instance:DAO_Test.HoaDonChiTietDAO_Test@68e5eea7] should have thrown an exception of type class com.microsoft.sqlserver.jdbc.SQLServerException" type="org.testng.TestException">
      <![CDATA[org.testng.TestException: 
Method HoaDonChiTietDAO_Test.TestInsert_NullMaSP_Fail()[pri:0, instance:DAO_Test.HoaDonChiTietDAO_Test@68e5eea7] should have thrown an exception of type class com.microsoft.sqlserver.jdbc.SQLServerException
at org.testng.internal.ExpectedExceptionsHolder.noException(ExpectedExceptionsHolder.java:82)
at org.testng.internal.TestInvoker.considerExceptions(TestInvoker.java:749)
at org.testng.internal.TestInvoker.invokeMethod(TestInvoker.java:634)
at org.testng.internal.TestInvoker.invokeTestMethod(TestInvoker.java:173)
at org.testng.internal.MethodRunner.runInSequence(MethodRunner.java:46)
at org.testng.internal.TestInvoker$MethodInvocationAgent.invoke(TestInvoker.java:824)
at org.testng.internal.TestInvoker.invokeTestMethods(TestInvoker.java:146)
at org.testng.internal.TestMethodWorker.invokeTestMethods(TestMethodWorker.java:146)
at org.testng.internal.TestMethodWorker.run(TestMethodWorker.java:128)
at java.base/java.util.ArrayList.forEach(ArrayList.java:1511)
at org.testng.TestRunner.privateRun(TestRunner.java:794)
at org.testng.TestRunner.run(TestRunner.java:596)
at org.testng.SuiteRunner.runTest(SuiteRunner.java:377)
at org.testng.SuiteRunner.runSequentially(SuiteRunner.java:371)
at org.testng.SuiteRunner.privateRun(SuiteRunner.java:332)
at org.testng.SuiteRunner.run(SuiteRunner.java:276)
at org.testng.SuiteRunnerWorker.runSuite(SuiteRunnerWorker.java:53)
at org.testng.SuiteRunnerWorker.run(SuiteRunnerWorker.java:96)
at org.testng.TestNG.runSuitesSequentially(TestNG.java:1212)
at org.testng.TestNG.runSuitesLocally(TestNG.java:1134)
at org.testng.TestNG.runSuites(TestNG.java:1063)
at org.testng.TestNG.run(TestNG.java:1031)
at org.testng.remote.AbstractRemoteTestNG.run(AbstractRemoteTestNG.java:115)
at org.testng.remote.RemoteTestNG.initAndRun(RemoteTestNG.java:251)
at org.testng.remote.RemoteTestNG.main(RemoteTestNG.java:77)
]]>
    </error>
  </testcase> <!-- TestInsert_NullMaSP_Fail -->
  <system-out/>
  <testcase classname="DAO_Test.HoaDonChiTietDAO_Test" name="TestSelect_getTien_ThanhToan_Fail" time="0.035">
    <error message="
Expected exception of type class com.microsoft.sqlserver.jdbc.SQLServerException but got java.lang.AssertionError: expected [null] but found [[]]" type="org.testng.TestException">
      <![CDATA[org.testng.TestException: 
Expected exception of type class com.microsoft.sqlserver.jdbc.SQLServerException but got java.lang.AssertionError: expected [null] but found [[]]
at org.testng.internal.ExpectedExceptionsHolder.wrongException(ExpectedExceptionsHolder.java:68)
at org.testng.internal.TestInvoker.considerExceptions(TestInvoker.java:739)
at org.testng.internal.TestInvoker.invokeMethod(TestInvoker.java:634)
at org.testng.internal.TestInvoker.invokeTestMethod(TestInvoker.java:173)
at org.testng.internal.MethodRunner.runInSequence(MethodRunner.java:46)
at org.testng.internal.TestInvoker$MethodInvocationAgent.invoke(TestInvoker.java:824)
at org.testng.internal.TestInvoker.invokeTestMethods(TestInvoker.java:146)
at org.testng.internal.TestMethodWorker.invokeTestMethods(TestMethodWorker.java:146)
at org.testng.internal.TestMethodWorker.run(TestMethodWorker.java:128)
at java.base/java.util.ArrayList.forEach(ArrayList.java:1511)
at org.testng.TestRunner.privateRun(TestRunner.java:794)
at org.testng.TestRunner.run(TestRunner.java:596)
at org.testng.SuiteRunner.runTest(SuiteRunner.java:377)
at org.testng.SuiteRunner.runSequentially(SuiteRunner.java:371)
at org.testng.SuiteRunner.privateRun(SuiteRunner.java:332)
at org.testng.SuiteRunner.run(SuiteRunner.java:276)
at org.testng.SuiteRunnerWorker.runSuite(SuiteRunnerWorker.java:53)
at org.testng.SuiteRunnerWorker.run(SuiteRunnerWorker.java:96)
at org.testng.TestNG.runSuitesSequentially(TestNG.java:1212)
at org.testng.TestNG.runSuitesLocally(TestNG.java:1134)
at org.testng.TestNG.runSuites(TestNG.java:1063)
at org.testng.TestNG.run(TestNG.java:1031)
at org.testng.remote.AbstractRemoteTestNG.run(AbstractRemoteTestNG.java:115)
at org.testng.remote.RemoteTestNG.initAndRun(RemoteTestNG.java:251)
at org.testng.remote.RemoteTestNG.main(RemoteTestNG.java:77)
Caused by: java.lang.AssertionError: expected [null] but found [[]]
at org.testng.Assert.fail(Assert.java:99)
at org.testng.Assert.failNotSame(Assert.java:1033)
at org.testng.Assert.assertNull(Assert.java:965)
at org.testng.Assert.assertNull(Assert.java:953)
at DAO_Test.HoaDonChiTietDAO_Test.TestSelect_getTien_ThanhToan_Fail(HoaDonChiTietDAO_Test.java:377)
at java.base/jdk.internal.reflect.DirectMethodHandleAccessor.invoke(DirectMethodHandleAccessor.java:104)
at java.base/java.lang.reflect.Method.invoke(Method.java:578)
at org.testng.internal.MethodInvocationHelper.invokeMethod(MethodInvocationHelper.java:133)
at org.testng.internal.TestInvoker.invokeMethod(TestInvoker.java:598)
... 22 more
]]>
    </error>
  </testcase> <!-- TestSelect_getTien_ThanhToan_Fail -->
  <system-out/>
  <testcase classname="DAO_Test.HoaDonChiTietDAO_Test" name="TestSelecte_All_Fail" time="0.041">
    <error message="
Expected exception of type class com.microsoft.sqlserver.jdbc.SQLServerException but got java.lang.AssertionError: expected [null] but found [[Entity.HoaDonChiTiet@5d8bafa9, Entity.HoaDonChiTiet@576f63f6, Entity.HoaDonChiTiet@2dca0d64, Entity.HoaDonChiTiet@f80945f, Entity.HoaDonChiTiet@ff684e1, Entity.HoaDonChiTiet@23aa363a, Entity.HoaDonChiTiet@5ef6ae06, Entity.HoaDonChiTiet@55dfebeb, Entity.HoaDonChiTiet@6e35bc3d, Entity.HoaDonChiTiet@1cdc4c27]]" type="org.testng.TestException">
      <![CDATA[org.testng.TestException: 
Expected exception of type class com.microsoft.sqlserver.jdbc.SQLServerException but got java.lang.AssertionError: expected [null] but found [[Entity.HoaDonChiTiet@5d8bafa9, Entity.HoaDonChiTiet@576f63f6, Entity.HoaDonChiTiet@2dca0d64, Entity.HoaDonChiTiet@f80945f, Entity.HoaDonChiTiet@ff684e1, Entity.HoaDonChiTiet@23aa363a, Entity.HoaDonChiTiet@5ef6ae06, Entity.HoaDonChiTiet@55dfebeb, Entity.HoaDonChiTiet@6e35bc3d, Entity.HoaDonChiTiet@1cdc4c27]]
at org.testng.internal.ExpectedExceptionsHolder.wrongException(ExpectedExceptionsHolder.java:68)
at org.testng.internal.TestInvoker.considerExceptions(TestInvoker.java:739)
at org.testng.internal.TestInvoker.invokeMethod(TestInvoker.java:634)
at org.testng.internal.TestInvoker.invokeTestMethod(TestInvoker.java:173)
at org.testng.internal.MethodRunner.runInSequence(MethodRunner.java:46)
at org.testng.internal.TestInvoker$MethodInvocationAgent.invoke(TestInvoker.java:824)
at org.testng.internal.TestInvoker.invokeTestMethods(TestInvoker.java:146)
at org.testng.internal.TestMethodWorker.invokeTestMethods(TestMethodWorker.java:146)
at org.testng.internal.TestMethodWorker.run(TestMethodWorker.java:128)
at java.base/java.util.ArrayList.forEach(ArrayList.java:1511)
at org.testng.TestRunner.privateRun(TestRunner.java:794)
at org.testng.TestRunner.run(TestRunner.java:596)
at org.testng.SuiteRunner.runTest(SuiteRunner.java:377)
at org.testng.SuiteRunner.runSequentially(SuiteRunner.java:371)
at org.testng.SuiteRunner.privateRun(SuiteRunner.java:332)
at org.testng.SuiteRunner.run(SuiteRunner.java:276)
at org.testng.SuiteRunnerWorker.runSuite(SuiteRunnerWorker.java:53)
at org.testng.SuiteRunnerWorker.run(SuiteRunnerWorker.java:96)
at org.testng.TestNG.runSuitesSequentially(TestNG.java:1212)
at org.testng.TestNG.runSuitesLocally(TestNG.java:1134)
at org.testng.TestNG.runSuites(TestNG.java:1063)
at org.testng.TestNG.run(TestNG.java:1031)
at org.testng.remote.AbstractRemoteTestNG.run(AbstractRemoteTestNG.java:115)
at org.testng.remote.RemoteTestNG.initAndRun(RemoteTestNG.java:251)
at org.testng.remote.RemoteTestNG.main(RemoteTestNG.java:77)
Caused by: java.lang.AssertionError: expected [null] but found [[Entity.HoaDonChiTiet@5d8bafa9, Entity.HoaDonChiTiet@576f63f6, Entity.HoaDonChiTiet@2dca0d64, Entity.HoaDonChiTiet@f80945f, Entity.HoaDonChiTiet@ff684e1, Entity.HoaDonChiTiet@23aa363a, Entity.HoaDonChiTiet@5ef6ae06, Entity.HoaDonChiTiet@55dfebeb, Entity.HoaDonChiTiet@6e35bc3d, Entity.HoaDonChiTiet@1cdc4c27]]
at org.testng.Assert.fail(Assert.java:99)
at org.testng.Assert.failNotSame(Assert.java:1033)
at org.testng.Assert.assertNull(Assert.java:965)
at org.testng.Assert.assertNull(Assert.java:953)
at DAO_Test.HoaDonChiTietDAO_Test.TestSelecte_All_Fail(HoaDonChiTietDAO_Test.java:260)
at java.base/jdk.internal.reflect.DirectMethodHandleAccessor.invoke(DirectMethodHandleAccessor.java:104)
at java.base/java.lang.reflect.Method.invoke(Method.java:578)
at org.testng.internal.MethodInvocationHelper.invokeMethod(MethodInvocationHelper.java:133)
at org.testng.internal.TestInvoker.invokeMethod(TestInvoker.java:598)
... 22 more
]]>
    </error>
  </testcase> <!-- TestSelecte_All_Fail -->
  <system-out/>
  <testcase classname="DAO_Test.HoaDonChiTietDAO_Test" name="TestUpdate_ALL_Pass" time="0.054"/>
  <system-out/>
  <testcase classname="DAO_Test.HoaDonChiTietDAO_Test" name="TestSelect_BySQL_Fail" time="0.040">
    <error message="
Expected exception of type class com.microsoft.sqlserver.jdbc.SQLServerException but got java.lang.AssertionError: expected [null] but found [[]]" type="org.testng.TestException">
      <![CDATA[org.testng.TestException: 
Expected exception of type class com.microsoft.sqlserver.jdbc.SQLServerException but got java.lang.AssertionError: expected [null] but found [[]]
at org.testng.internal.ExpectedExceptionsHolder.wrongException(ExpectedExceptionsHolder.java:68)
at org.testng.internal.TestInvoker.considerExceptions(TestInvoker.java:739)
at org.testng.internal.TestInvoker.invokeMethod(TestInvoker.java:634)
at org.testng.internal.TestInvoker.invokeTestMethod(TestInvoker.java:173)
at org.testng.internal.MethodRunner.runInSequence(MethodRunner.java:46)
at org.testng.internal.TestInvoker$MethodInvocationAgent.invoke(TestInvoker.java:824)
at org.testng.internal.TestInvoker.invokeTestMethods(TestInvoker.java:146)
at org.testng.internal.TestMethodWorker.invokeTestMethods(TestMethodWorker.java:146)
at org.testng.internal.TestMethodWorker.run(TestMethodWorker.java:128)
at java.base/java.util.ArrayList.forEach(ArrayList.java:1511)
at org.testng.TestRunner.privateRun(TestRunner.java:794)
at org.testng.TestRunner.run(TestRunner.java:596)
at org.testng.SuiteRunner.runTest(SuiteRunner.java:377)
at org.testng.SuiteRunner.runSequentially(SuiteRunner.java:371)
at org.testng.SuiteRunner.privateRun(SuiteRunner.java:332)
at org.testng.SuiteRunner.run(SuiteRunner.java:276)
at org.testng.SuiteRunnerWorker.runSuite(SuiteRunnerWorker.java:53)
at org.testng.SuiteRunnerWorker.run(SuiteRunnerWorker.java:96)
at org.testng.TestNG.runSuitesSequentially(TestNG.java:1212)
at org.testng.TestNG.runSuitesLocally(TestNG.java:1134)
at org.testng.TestNG.runSuites(TestNG.java:1063)
at org.testng.TestNG.run(TestNG.java:1031)
at org.testng.remote.AbstractRemoteTestNG.run(AbstractRemoteTestNG.java:115)
at org.testng.remote.RemoteTestNG.initAndRun(RemoteTestNG.java:251)
at org.testng.remote.RemoteTestNG.main(RemoteTestNG.java:77)
Caused by: java.lang.AssertionError: expected [null] but found [[]]
at org.testng.Assert.fail(Assert.java:99)
at org.testng.Assert.failNotSame(Assert.java:1033)
at org.testng.Assert.assertNull(Assert.java:965)
at org.testng.Assert.assertNull(Assert.java:953)
at DAO_Test.HoaDonChiTietDAO_Test.TestSelect_BySQL_Fail(HoaDonChiTietDAO_Test.java:300)
at java.base/jdk.internal.reflect.DirectMethodHandleAccessor.invoke(DirectMethodHandleAccessor.java:104)
at java.base/java.lang.reflect.Method.invoke(Method.java:578)
at org.testng.internal.MethodInvocationHelper.invokeMethod(MethodInvocationHelper.java:133)
at org.testng.internal.TestInvoker.invokeMethod(TestInvoker.java:598)
... 22 more
]]>
    </error>
  </testcase> <!-- TestSelect_BySQL_Fail -->
  <system-out/>
  <testcase classname="DAO_Test.HoaDonChiTietDAO_Test" name="TestUpdate_Soluong_Pass" time="0.045"/>
  <system-out/>
  <testcase classname="DAO_Test.HoaDonChiTietDAO_Test" name="TestSelect_getTHONGTIN_KHACHHANG_NHANVIEN_Fail" time="0.031">
    <error message="
Expected exception of type class com.microsoft.sqlserver.jdbc.SQLServerException but got java.lang.AssertionError: expected [null] but found [[]]" type="org.testng.TestException">
      <![CDATA[org.testng.TestException: 
Expected exception of type class com.microsoft.sqlserver.jdbc.SQLServerException but got java.lang.AssertionError: expected [null] but found [[]]
at org.testng.internal.ExpectedExceptionsHolder.wrongException(ExpectedExceptionsHolder.java:68)
at org.testng.internal.TestInvoker.considerExceptions(TestInvoker.java:739)
at org.testng.internal.TestInvoker.invokeMethod(TestInvoker.java:634)
at org.testng.internal.TestInvoker.invokeTestMethod(TestInvoker.java:173)
at org.testng.internal.MethodRunner.runInSequence(MethodRunner.java:46)
at org.testng.internal.TestInvoker$MethodInvocationAgent.invoke(TestInvoker.java:824)
at org.testng.internal.TestInvoker.invokeTestMethods(TestInvoker.java:146)
at org.testng.internal.TestMethodWorker.invokeTestMethods(TestMethodWorker.java:146)
at org.testng.internal.TestMethodWorker.run(TestMethodWorker.java:128)
at java.base/java.util.ArrayList.forEach(ArrayList.java:1511)
at org.testng.TestRunner.privateRun(TestRunner.java:794)
at org.testng.TestRunner.run(TestRunner.java:596)
at org.testng.SuiteRunner.runTest(SuiteRunner.java:377)
at org.testng.SuiteRunner.runSequentially(SuiteRunner.java:371)
at org.testng.SuiteRunner.privateRun(SuiteRunner.java:332)
at org.testng.SuiteRunner.run(SuiteRunner.java:276)
at org.testng.SuiteRunnerWorker.runSuite(SuiteRunnerWorker.java:53)
at org.testng.SuiteRunnerWorker.run(SuiteRunnerWorker.java:96)
at org.testng.TestNG.runSuitesSequentially(TestNG.java:1212)
at org.testng.TestNG.runSuitesLocally(TestNG.java:1134)
at org.testng.TestNG.runSuites(TestNG.java:1063)
at org.testng.TestNG.run(TestNG.java:1031)
at org.testng.remote.AbstractRemoteTestNG.run(AbstractRemoteTestNG.java:115)
at org.testng.remote.RemoteTestNG.initAndRun(RemoteTestNG.java:251)
at org.testng.remote.RemoteTestNG.main(RemoteTestNG.java:77)
Caused by: java.lang.AssertionError: expected [null] but found [[]]
at org.testng.Assert.fail(Assert.java:99)
at org.testng.Assert.failNotSame(Assert.java:1033)
at org.testng.Assert.assertNull(Assert.java:965)
at org.testng.Assert.assertNull(Assert.java:953)
at DAO_Test.HoaDonChiTietDAO_Test.TestSelect_getTHONGTIN_KHACHHANG_NHANVIEN_Fail(HoaDonChiTietDAO_Test.java:339)
at java.base/jdk.internal.reflect.DirectMethodHandleAccessor.invoke(DirectMethodHandleAccessor.java:104)
at java.base/java.lang.reflect.Method.invoke(Method.java:578)
at org.testng.internal.MethodInvocationHelper.invokeMethod(MethodInvocationHelper.java:133)
at org.testng.internal.TestInvoker.invokeMethod(TestInvoker.java:598)
... 22 more
]]>
    </error>
  </testcase> <!-- TestSelect_getTHONGTIN_KHACHHANG_NHANVIEN_Fail -->
  <system-out/>
  <testcase classname="DAO_Test.HoaDonChiTietDAO_Test" name="TestInsert_soluong_Fail" time="0.062">
    <error message="
Method HoaDonChiTietDAO_Test.TestInsert_soluong_Fail()[pri:0, instance:DAO_Test.HoaDonChiTietDAO_Test@68e5eea7] should have thrown an exception of type class com.microsoft.sqlserver.jdbc.SQLServerException" type="org.testng.TestException">
      <![CDATA[org.testng.TestException: 
Method HoaDonChiTietDAO_Test.TestInsert_soluong_Fail()[pri:0, instance:DAO_Test.HoaDonChiTietDAO_Test@68e5eea7] should have thrown an exception of type class com.microsoft.sqlserver.jdbc.SQLServerException
at org.testng.internal.ExpectedExceptionsHolder.noException(ExpectedExceptionsHolder.java:82)
at org.testng.internal.TestInvoker.considerExceptions(TestInvoker.java:749)
at org.testng.internal.TestInvoker.invokeMethod(TestInvoker.java:634)
at org.testng.internal.TestInvoker.invokeTestMethod(TestInvoker.java:173)
at org.testng.internal.MethodRunner.runInSequence(MethodRunner.java:46)
at org.testng.internal.TestInvoker$MethodInvocationAgent.invoke(TestInvoker.java:824)
at org.testng.internal.TestInvoker.invokeTestMethods(TestInvoker.java:146)
at org.testng.internal.TestMethodWorker.invokeTestMethods(TestMethodWorker.java:146)
at org.testng.internal.TestMethodWorker.run(TestMethodWorker.java:128)
at java.base/java.util.ArrayList.forEach(ArrayList.java:1511)
at org.testng.TestRunner.privateRun(TestRunner.java:794)
at org.testng.TestRunner.run(TestRunner.java:596)
at org.testng.SuiteRunner.runTest(SuiteRunner.java:377)
at org.testng.SuiteRunner.runSequentially(SuiteRunner.java:371)
at org.testng.SuiteRunner.privateRun(SuiteRunner.java:332)
at org.testng.SuiteRunner.run(SuiteRunner.java:276)
at org.testng.SuiteRunnerWorker.runSuite(SuiteRunnerWorker.java:53)
at org.testng.SuiteRunnerWorker.run(SuiteRunnerWorker.java:96)
at org.testng.TestNG.runSuitesSequentially(TestNG.java:1212)
at org.testng.TestNG.runSuitesLocally(TestNG.java:1134)
at org.testng.TestNG.runSuites(TestNG.java:1063)
at org.testng.TestNG.run(TestNG.java:1031)
at org.testng.remote.AbstractRemoteTestNG.run(AbstractRemoteTestNG.java:115)
at org.testng.remote.RemoteTestNG.initAndRun(RemoteTestNG.java:251)
at org.testng.remote.RemoteTestNG.main(RemoteTestNG.java:77)
]]>
    </error>
  </testcase> <!-- TestInsert_soluong_Fail -->
  <system-out/>
  <testcase classname="DAO_Test.HoaDonChiTietDAO_Test" name="TestDelete_Pass" time="2.053"/>
  <system-out/>
  <testcase classname="DAO_Test.HoaDonChiTietDAO_Test" name="TestSelect_BySQL_Pass" time="0.049"/>
  <system-out/>
  <testcase classname="DAO_Test.HoaDonChiTietDAO_Test" name="TestSelecte_ByID_Pass" time="0.025">
    <failure message="expected object to not be null" type="java.lang.AssertionError">
      <![CDATA[java.lang.AssertionError: expected object to not be null
at org.testng.Assert.fail(Assert.java:99)
at org.testng.Assert.assertNotNull(Assert.java:942)
at org.testng.Assert.assertNotNull(Assert.java:926)
at DAO_Test.HoaDonChiTietDAO_Test.TestSelecte_ByID_Pass(HoaDonChiTietDAO_Test.java:269)
at java.base/jdk.internal.reflect.DirectMethodHandleAccessor.invoke(DirectMethodHandleAccessor.java:104)
at java.base/java.lang.reflect.Method.invoke(Method.java:578)
at org.testng.internal.MethodInvocationHelper.invokeMethod(MethodInvocationHelper.java:133)
at org.testng.internal.TestInvoker.invokeMethod(TestInvoker.java:598)
at org.testng.internal.TestInvoker.invokeTestMethod(TestInvoker.java:173)
at org.testng.internal.MethodRunner.runInSequence(MethodRunner.java:46)
at org.testng.internal.TestInvoker$MethodInvocationAgent.invoke(TestInvoker.java:824)
at org.testng.internal.TestInvoker.invokeTestMethods(TestInvoker.java:146)
at org.testng.internal.TestMethodWorker.invokeTestMethods(TestMethodWorker.java:146)
at org.testng.internal.TestMethodWorker.run(TestMethodWorker.java:128)
at java.base/java.util.ArrayList.forEach(ArrayList.java:1511)
at org.testng.TestRunner.privateRun(TestRunner.java:794)
at org.testng.TestRunner.run(TestRunner.java:596)
at org.testng.SuiteRunner.runTest(SuiteRunner.java:377)
at org.testng.SuiteRunner.runSequentially(SuiteRunner.java:371)
at org.testng.SuiteRunner.privateRun(SuiteRunner.java:332)
at org.testng.SuiteRunner.run(SuiteRunner.java:276)
at org.testng.SuiteRunnerWorker.runSuite(SuiteRunnerWorker.java:53)
at org.testng.SuiteRunnerWorker.run(SuiteRunnerWorker.java:96)
at org.testng.TestNG.runSuitesSequentially(TestNG.java:1212)
at org.testng.TestNG.runSuitesLocally(TestNG.java:1134)
at org.testng.TestNG.runSuites(TestNG.java:1063)
at org.testng.TestNG.run(TestNG.java:1031)
at org.testng.remote.AbstractRemoteTestNG.run(AbstractRemoteTestNG.java:115)
at org.testng.remote.RemoteTestNG.initAndRun(RemoteTestNG.java:251)
at org.testng.remote.RemoteTestNG.main(RemoteTestNG.java:77)
]]>
    </failure>
  </testcase> <!-- TestSelecte_ByID_Pass -->
  <system-out/>
  <testcase classname="DAO_Test.HoaDonChiTietDAO_Test" name="TestUpdate_MaSP_Pass" time="0.053"/>
  <system-out/>
  <testcase classname="DAO_Test.HoaDonChiTietDAO_Test" name="TestSelect_update_SoLuong_SanPham_Pass" time="0.073">
    <failure message="expected object to not be null" type="java.lang.AssertionError">
      <![CDATA[java.lang.AssertionError: expected object to not be null
at org.testng.Assert.fail(Assert.java:99)
at org.testng.Assert.assertNotNull(Assert.java:942)
at org.testng.Assert.assertNotNull(Assert.java:926)
at DAO_Test.HoaDonChiTietDAO_Test.TestSelect_update_SoLuong_SanPham_Pass(HoaDonChiTietDAO_Test.java:428)
at java.base/jdk.internal.reflect.DirectMethodHandleAccessor.invoke(DirectMethodHandleAccessor.java:104)
at java.base/java.lang.reflect.Method.invoke(Method.java:578)
at org.testng.internal.MethodInvocationHelper.invokeMethod(MethodInvocationHelper.java:133)
at org.testng.internal.TestInvoker.invokeMethod(TestInvoker.java:598)
at org.testng.internal.TestInvoker.invokeTestMethod(TestInvoker.java:173)
at org.testng.internal.MethodRunner.runInSequence(MethodRunner.java:46)
at org.testng.internal.TestInvoker$MethodInvocationAgent.invoke(TestInvoker.java:824)
at org.testng.internal.TestInvoker.invokeTestMethods(TestInvoker.java:146)
at org.testng.internal.TestMethodWorker.invokeTestMethods(TestMethodWorker.java:146)
at org.testng.internal.TestMethodWorker.run(TestMethodWorker.java:128)
at java.base/java.util.ArrayList.forEach(ArrayList.java:1511)
at org.testng.TestRunner.privateRun(TestRunner.java:794)
at org.testng.TestRunner.run(TestRunner.java:596)
at org.testng.SuiteRunner.runTest(SuiteRunner.java:377)
at org.testng.SuiteRunner.runSequentially(SuiteRunner.java:371)
at org.testng.SuiteRunner.privateRun(SuiteRunner.java:332)
at org.testng.SuiteRunner.run(SuiteRunner.java:276)
at org.testng.SuiteRunnerWorker.runSuite(SuiteRunnerWorker.java:53)
at org.testng.SuiteRunnerWorker.run(SuiteRunnerWorker.java:96)
at org.testng.TestNG.runSuitesSequentially(TestNG.java:1212)
at org.testng.TestNG.runSuitesLocally(TestNG.java:1134)
at org.testng.TestNG.runSuites(TestNG.java:1063)
at org.testng.TestNG.run(TestNG.java:1031)
at org.testng.remote.AbstractRemoteTestNG.run(AbstractRemoteTestNG.java:115)
at org.testng.remote.RemoteTestNG.initAndRun(RemoteTestNG.java:251)
at org.testng.remote.RemoteTestNG.main(RemoteTestNG.java:77)
]]>
    </failure>
  </testcase> <!-- TestSelect_update_SoLuong_SanPham_Pass -->
  <system-out/>
  <testcase classname="DAO_Test.HoaDonChiTietDAO_Test" name="TestSelect_getTien_ThanhToan_Pass" time="0.036"/>
  <system-out/>
  <testcase classname="DAO_Test.HoaDonChiTietDAO_Test" name="TestInsert_NullMaHD_Fail" time="0.063">
    <error message="
Method HoaDonChiTietDAO_Test.TestInsert_NullMaHD_Fail()[pri:0, instance:DAO_Test.HoaDonChiTietDAO_Test@68e5eea7] should have thrown an exception of type class com.microsoft.sqlserver.jdbc.SQLServerException" type="org.testng.TestException">
      <![CDATA[org.testng.TestException: 
Method HoaDonChiTietDAO_Test.TestInsert_NullMaHD_Fail()[pri:0, instance:DAO_Test.HoaDonChiTietDAO_Test@68e5eea7] should have thrown an exception of type class com.microsoft.sqlserver.jdbc.SQLServerException
at org.testng.internal.ExpectedExceptionsHolder.noException(ExpectedExceptionsHolder.java:82)
at org.testng.internal.TestInvoker.considerExceptions(TestInvoker.java:749)
at org.testng.internal.TestInvoker.invokeMethod(TestInvoker.java:634)
at org.testng.internal.TestInvoker.invokeTestMethod(TestInvoker.java:173)
at org.testng.internal.MethodRunner.runInSequence(MethodRunner.java:46)
at org.testng.internal.TestInvoker$MethodInvocationAgent.invoke(TestInvoker.java:824)
at org.testng.internal.TestInvoker.invokeTestMethods(TestInvoker.java:146)
at org.testng.internal.TestMethodWorker.invokeTestMethods(TestMethodWorker.java:146)
at org.testng.internal.TestMethodWorker.run(TestMethodWorker.java:128)
at java.base/java.util.ArrayList.forEach(ArrayList.java:1511)
at org.testng.TestRunner.privateRun(TestRunner.java:794)
at org.testng.TestRunner.run(TestRunner.java:596)
at org.testng.SuiteRunner.runTest(SuiteRunner.java:377)
at org.testng.SuiteRunner.runSequentially(SuiteRunner.java:371)
at org.testng.SuiteRunner.privateRun(SuiteRunner.java:332)
at org.testng.SuiteRunner.run(SuiteRunner.java:276)
at org.testng.SuiteRunnerWorker.runSuite(SuiteRunnerWorker.java:53)
at org.testng.SuiteRunnerWorker.run(SuiteRunnerWorker.java:96)
at org.testng.TestNG.runSuitesSequentially(TestNG.java:1212)
at org.testng.TestNG.runSuitesLocally(TestNG.java:1134)
at org.testng.TestNG.runSuites(TestNG.java:1063)
at org.testng.TestNG.run(TestNG.java:1031)
at org.testng.remote.AbstractRemoteTestNG.run(AbstractRemoteTestNG.java:115)
at org.testng.remote.RemoteTestNG.initAndRun(RemoteTestNG.java:251)
at org.testng.remote.RemoteTestNG.main(RemoteTestNG.java:77)
]]>
    </error>
  </testcase> <!-- TestInsert_NullMaHD_Fail -->
  <system-out/>
  <testcase classname="DAO_Test.HoaDonChiTietDAO_Test" name="TestSelect_getThanhToan_Fail" time="0.060">
    <error message="
Expected exception of type class com.microsoft.sqlserver.jdbc.SQLServerException but got java.lang.AssertionError: expected [null] but found [[]]" type="org.testng.TestException">
      <![CDATA[org.testng.TestException: 
Expected exception of type class com.microsoft.sqlserver.jdbc.SQLServerException but got java.lang.AssertionError: expected [null] but found [[]]
at org.testng.internal.ExpectedExceptionsHolder.wrongException(ExpectedExceptionsHolder.java:68)
at org.testng.internal.TestInvoker.considerExceptions(TestInvoker.java:739)
at org.testng.internal.TestInvoker.invokeMethod(TestInvoker.java:634)
at org.testng.internal.TestInvoker.invokeTestMethod(TestInvoker.java:173)
at org.testng.internal.MethodRunner.runInSequence(MethodRunner.java:46)
at org.testng.internal.TestInvoker$MethodInvocationAgent.invoke(TestInvoker.java:824)
at org.testng.internal.TestInvoker.invokeTestMethods(TestInvoker.java:146)
at org.testng.internal.TestMethodWorker.invokeTestMethods(TestMethodWorker.java:146)
at org.testng.internal.TestMethodWorker.run(TestMethodWorker.java:128)
at java.base/java.util.ArrayList.forEach(ArrayList.java:1511)
at org.testng.TestRunner.privateRun(TestRunner.java:794)
at org.testng.TestRunner.run(TestRunner.java:596)
at org.testng.SuiteRunner.runTest(SuiteRunner.java:377)
at org.testng.SuiteRunner.runSequentially(SuiteRunner.java:371)
at org.testng.SuiteRunner.privateRun(SuiteRunner.java:332)
at org.testng.SuiteRunner.run(SuiteRunner.java:276)
at org.testng.SuiteRunnerWorker.runSuite(SuiteRunnerWorker.java:53)
at org.testng.SuiteRunnerWorker.run(SuiteRunnerWorker.java:96)
at org.testng.TestNG.runSuitesSequentially(TestNG.java:1212)
at org.testng.TestNG.runSuitesLocally(TestNG.java:1134)
at org.testng.TestNG.runSuites(TestNG.java:1063)
at org.testng.TestNG.run(TestNG.java:1031)
at org.testng.remote.AbstractRemoteTestNG.run(AbstractRemoteTestNG.java:115)
at org.testng.remote.RemoteTestNG.initAndRun(RemoteTestNG.java:251)
at org.testng.remote.RemoteTestNG.main(RemoteTestNG.java:77)
Caused by: java.lang.AssertionError: expected [null] but found [[]]
at org.testng.Assert.fail(Assert.java:99)
at org.testng.Assert.failNotSame(Assert.java:1033)
at org.testng.Assert.assertNull(Assert.java:965)
at org.testng.Assert.assertNull(Assert.java:953)
at DAO_Test.HoaDonChiTietDAO_Test.TestSelect_getThanhToan_Fail(HoaDonChiTietDAO_Test.java:358)
at java.base/jdk.internal.reflect.DirectMethodHandleAccessor.invoke(DirectMethodHandleAccessor.java:104)
at java.base/java.lang.reflect.Method.invoke(Method.java:578)
at org.testng.internal.MethodInvocationHelper.invokeMethod(MethodInvocationHelper.java:133)
at org.testng.internal.TestInvoker.invokeMethod(TestInvoker.java:598)
... 22 more
]]>
    </error>
  </testcase> <!-- TestSelect_getThanhToan_Fail -->
  <system-out/>
  <testcase classname="DAO_Test.HoaDonChiTietDAO_Test" name="TestUpdate_MAHD_Pass" time="0.059"/>
  <system-out/>
  <testcase classname="DAO_Test.HoaDonChiTietDAO_Test" name="TestInsert_All_Fail" time="0.285">
    <error message="
Method HoaDonChiTietDAO_Test.TestInsert_All_Fail()[pri:0, instance:DAO_Test.HoaDonChiTietDAO_Test@68e5eea7] should have thrown an exception of type class com.microsoft.sqlserver.jdbc.SQLServerException" type="org.testng.TestException">
      <![CDATA[org.testng.TestException: 
Method HoaDonChiTietDAO_Test.TestInsert_All_Fail()[pri:0, instance:DAO_Test.HoaDonChiTietDAO_Test@68e5eea7] should have thrown an exception of type class com.microsoft.sqlserver.jdbc.SQLServerException
at org.testng.internal.ExpectedExceptionsHolder.noException(ExpectedExceptionsHolder.java:82)
at org.testng.internal.TestInvoker.considerExceptions(TestInvoker.java:749)
at org.testng.internal.TestInvoker.invokeMethod(TestInvoker.java:634)
at org.testng.internal.TestInvoker.invokeTestMethod(TestInvoker.java:173)
at org.testng.internal.MethodRunner.runInSequence(MethodRunner.java:46)
at org.testng.internal.TestInvoker$MethodInvocationAgent.invoke(TestInvoker.java:824)
at org.testng.internal.TestInvoker.invokeTestMethods(TestInvoker.java:146)
at org.testng.internal.TestMethodWorker.invokeTestMethods(TestMethodWorker.java:146)
at org.testng.internal.TestMethodWorker.run(TestMethodWorker.java:128)
at java.base/java.util.ArrayList.forEach(ArrayList.java:1511)
at org.testng.TestRunner.privateRun(TestRunner.java:794)
at org.testng.TestRunner.run(TestRunner.java:596)
at org.testng.SuiteRunner.runTest(SuiteRunner.java:377)
at org.testng.SuiteRunner.runSequentially(SuiteRunner.java:371)
at org.testng.SuiteRunner.privateRun(SuiteRunner.java:332)
at org.testng.SuiteRunner.run(SuiteRunner.java:276)
at org.testng.SuiteRunnerWorker.runSuite(SuiteRunnerWorker.java:53)
at org.testng.SuiteRunnerWorker.run(SuiteRunnerWorker.java:96)
at org.testng.TestNG.runSuitesSequentially(TestNG.java:1212)
at org.testng.TestNG.runSuitesLocally(TestNG.java:1134)
at org.testng.TestNG.runSuites(TestNG.java:1063)
at org.testng.TestNG.run(TestNG.java:1031)
at org.testng.remote.AbstractRemoteTestNG.run(AbstractRemoteTestNG.java:115)
at org.testng.remote.RemoteTestNG.initAndRun(RemoteTestNG.java:251)
at org.testng.remote.RemoteTestNG.main(RemoteTestNG.java:77)
]]>
    </error>
  </testcase> <!-- TestInsert_All_Fail -->
  <system-out/>
  <testcase classname="DAO_Test.HoaDonChiTietDAO_Test" name="TestInsert_Gia_Fail" time="0.077">
    <error message="
Method HoaDonChiTietDAO_Test.TestInsert_Gia_Fail()[pri:0, instance:DAO_Test.HoaDonChiTietDAO_Test@68e5eea7] should have thrown an exception of type class com.microsoft.sqlserver.jdbc.SQLServerException" type="org.testng.TestException">
      <![CDATA[org.testng.TestException: 
Method HoaDonChiTietDAO_Test.TestInsert_Gia_Fail()[pri:0, instance:DAO_Test.HoaDonChiTietDAO_Test@68e5eea7] should have thrown an exception of type class com.microsoft.sqlserver.jdbc.SQLServerException
at org.testng.internal.ExpectedExceptionsHolder.noException(ExpectedExceptionsHolder.java:82)
at org.testng.internal.TestInvoker.considerExceptions(TestInvoker.java:749)
at org.testng.internal.TestInvoker.invokeMethod(TestInvoker.java:634)
at org.testng.internal.TestInvoker.invokeTestMethod(TestInvoker.java:173)
at org.testng.internal.MethodRunner.runInSequence(MethodRunner.java:46)
at org.testng.internal.TestInvoker$MethodInvocationAgent.invoke(TestInvoker.java:824)
at org.testng.internal.TestInvoker.invokeTestMethods(TestInvoker.java:146)
at org.testng.internal.TestMethodWorker.invokeTestMethods(TestMethodWorker.java:146)
at org.testng.internal.TestMethodWorker.run(TestMethodWorker.java:128)
at java.base/java.util.ArrayList.forEach(ArrayList.java:1511)
at org.testng.TestRunner.privateRun(TestRunner.java:794)
at org.testng.TestRunner.run(TestRunner.java:596)
at org.testng.SuiteRunner.runTest(SuiteRunner.java:377)
at org.testng.SuiteRunner.runSequentially(SuiteRunner.java:371)
at org.testng.SuiteRunner.privateRun(SuiteRunner.java:332)
at org.testng.SuiteRunner.run(SuiteRunner.java:276)
at org.testng.SuiteRunnerWorker.runSuite(SuiteRunnerWorker.java:53)
at org.testng.SuiteRunnerWorker.run(SuiteRunnerWorker.java:96)
at org.testng.TestNG.runSuitesSequentially(TestNG.java:1212)
at org.testng.TestNG.runSuitesLocally(TestNG.java:1134)
at org.testng.TestNG.runSuites(TestNG.java:1063)
at org.testng.TestNG.run(TestNG.java:1031)
at org.testng.remote.AbstractRemoteTestNG.run(AbstractRemoteTestNG.java:115)
at org.testng.remote.RemoteTestNG.initAndRun(RemoteTestNG.java:251)
at org.testng.remote.RemoteTestNG.main(RemoteTestNG.java:77)
]]>
    </error>
  </testcase> <!-- TestInsert_Gia_Fail -->
  <system-out/>
  <testcase classname="DAO_Test.HoaDonChiTietDAO_Test" name="TestSelect_update_SoLuong_SanPham_Fail" time="0.077">
    <error message="
Method HoaDonChiTietDAO_Test.TestSelect_update_SoLuong_SanPham_Fail()[pri:0, instance:DAO_Test.HoaDonChiTietDAO_Test@68e5eea7] should have thrown an exception of type class com.microsoft.sqlserver.jdbc.SQLServerException" type="org.testng.TestException">
      <![CDATA[org.testng.TestException: 
Method HoaDonChiTietDAO_Test.TestSelect_update_SoLuong_SanPham_Fail()[pri:0, instance:DAO_Test.HoaDonChiTietDAO_Test@68e5eea7] should have thrown an exception of type class com.microsoft.sqlserver.jdbc.SQLServerException
at org.testng.internal.ExpectedExceptionsHolder.noException(ExpectedExceptionsHolder.java:82)
at org.testng.internal.TestInvoker.considerExceptions(TestInvoker.java:749)
at org.testng.internal.TestInvoker.invokeMethod(TestInvoker.java:634)
at org.testng.internal.TestInvoker.invokeTestMethod(TestInvoker.java:173)
at org.testng.internal.MethodRunner.runInSequence(MethodRunner.java:46)
at org.testng.internal.TestInvoker$MethodInvocationAgent.invoke(TestInvoker.java:824)
at org.testng.internal.TestInvoker.invokeTestMethods(TestInvoker.java:146)
at org.testng.internal.TestMethodWorker.invokeTestMethods(TestMethodWorker.java:146)
at org.testng.internal.TestMethodWorker.run(TestMethodWorker.java:128)
at java.base/java.util.ArrayList.forEach(ArrayList.java:1511)
at org.testng.TestRunner.privateRun(TestRunner.java:794)
at org.testng.TestRunner.run(TestRunner.java:596)
at org.testng.SuiteRunner.runTest(SuiteRunner.java:377)
at org.testng.SuiteRunner.runSequentially(SuiteRunner.java:371)
at org.testng.SuiteRunner.privateRun(SuiteRunner.java:332)
at org.testng.SuiteRunner.run(SuiteRunner.java:276)
at org.testng.SuiteRunnerWorker.runSuite(SuiteRunnerWorker.java:53)
at org.testng.SuiteRunnerWorker.run(SuiteRunnerWorker.java:96)
at org.testng.TestNG.runSuitesSequentially(TestNG.java:1212)
at org.testng.TestNG.runSuitesLocally(TestNG.java:1134)
at org.testng.TestNG.runSuites(TestNG.java:1063)
at org.testng.TestNG.run(TestNG.java:1031)
at org.testng.remote.AbstractRemoteTestNG.run(AbstractRemoteTestNG.java:115)
at org.testng.remote.RemoteTestNG.initAndRun(RemoteTestNG.java:251)
at org.testng.remote.RemoteTestNG.main(RemoteTestNG.java:77)
]]>
    </error>
  </testcase> <!-- TestSelect_update_SoLuong_SanPham_Fail -->
  <system-out/>
  <testcase classname="DAO_Test.HoaDonChiTietDAO_Test" name="TestUpdate_ALL_Fail" time="0.002">
    <error message="
Method HoaDonChiTietDAO_Test.TestUpdate_ALL_Fail()[pri:0, instance:DAO_Test.HoaDonChiTietDAO_Test@68e5eea7] should have thrown an exception of type class com.microsoft.sqlserver.jdbc.SQLServerException" type="org.testng.TestException">
      <![CDATA[org.testng.TestException: 
Method HoaDonChiTietDAO_Test.TestUpdate_ALL_Fail()[pri:0, instance:DAO_Test.HoaDonChiTietDAO_Test@68e5eea7] should have thrown an exception of type class com.microsoft.sqlserver.jdbc.SQLServerException
at org.testng.internal.ExpectedExceptionsHolder.noException(ExpectedExceptionsHolder.java:82)
at org.testng.internal.TestInvoker.considerExceptions(TestInvoker.java:749)
at org.testng.internal.TestInvoker.invokeMethod(TestInvoker.java:634)
at org.testng.internal.TestInvoker.invokeTestMethod(TestInvoker.java:173)
at org.testng.internal.MethodRunner.runInSequence(MethodRunner.java:46)
at org.testng.internal.TestInvoker$MethodInvocationAgent.invoke(TestInvoker.java:824)
at org.testng.internal.TestInvoker.invokeTestMethods(TestInvoker.java:146)
at org.testng.internal.TestMethodWorker.invokeTestMethods(TestMethodWorker.java:146)
at org.testng.internal.TestMethodWorker.run(TestMethodWorker.java:128)
at java.base/java.util.ArrayList.forEach(ArrayList.java:1511)
at org.testng.TestRunner.privateRun(TestRunner.java:794)
at org.testng.TestRunner.run(TestRunner.java:596)
at org.testng.SuiteRunner.runTest(SuiteRunner.java:377)
at org.testng.SuiteRunner.runSequentially(SuiteRunner.java:371)
at org.testng.SuiteRunner.privateRun(SuiteRunner.java:332)
at org.testng.SuiteRunner.run(SuiteRunner.java:276)
at org.testng.SuiteRunnerWorker.runSuite(SuiteRunnerWorker.java:53)
at org.testng.SuiteRunnerWorker.run(SuiteRunnerWorker.java:96)
at org.testng.TestNG.runSuitesSequentially(TestNG.java:1212)
at org.testng.TestNG.runSuitesLocally(TestNG.java:1134)
at org.testng.TestNG.runSuites(TestNG.java:1063)
at org.testng.TestNG.run(TestNG.java:1031)
at org.testng.remote.AbstractRemoteTestNG.run(AbstractRemoteTestNG.java:115)
at org.testng.remote.RemoteTestNG.initAndRun(RemoteTestNG.java:251)
at org.testng.remote.RemoteTestNG.main(RemoteTestNG.java:77)
]]>
    </error>
  </testcase> <!-- TestUpdate_ALL_Fail -->
  <system-out/>
  <testcase classname="DAO_Test.HoaDonChiTietDAO_Test" name="TestInsert_NullGhiChu_Pass" time="0.096"/>
  <system-out/>
  <testcase classname="DAO_Test.HoaDonChiTietDAO_Test" name="TestSelect_selectby_MaHD_MASP_Fail" time="0.034">
    <error message="
Method HoaDonChiTietDAO_Test.TestSelect_selectby_MaHD_MASP_Fail()[pri:0, instance:DAO_Test.HoaDonChiTietDAO_Test@68e5eea7] should have thrown an exception of type class com.microsoft.sqlserver.jdbc.SQLServerException" type="org.testng.TestException">
      <![CDATA[org.testng.TestException: 
Method HoaDonChiTietDAO_Test.TestSelect_selectby_MaHD_MASP_Fail()[pri:0, instance:DAO_Test.HoaDonChiTietDAO_Test@68e5eea7] should have thrown an exception of type class com.microsoft.sqlserver.jdbc.SQLServerException
at org.testng.internal.ExpectedExceptionsHolder.noException(ExpectedExceptionsHolder.java:82)
at org.testng.internal.TestInvoker.considerExceptions(TestInvoker.java:749)
at org.testng.internal.TestInvoker.invokeMethod(TestInvoker.java:634)
at org.testng.internal.TestInvoker.invokeTestMethod(TestInvoker.java:173)
at org.testng.internal.MethodRunner.runInSequence(MethodRunner.java:46)
at org.testng.internal.TestInvoker$MethodInvocationAgent.invoke(TestInvoker.java:824)
at org.testng.internal.TestInvoker.invokeTestMethods(TestInvoker.java:146)
at org.testng.internal.TestMethodWorker.invokeTestMethods(TestMethodWorker.java:146)
at org.testng.internal.TestMethodWorker.run(TestMethodWorker.java:128)
at java.base/java.util.ArrayList.forEach(ArrayList.java:1511)
at org.testng.TestRunner.privateRun(TestRunner.java:794)
at org.testng.TestRunner.run(TestRunner.java:596)
at org.testng.SuiteRunner.runTest(SuiteRunner.java:377)
at org.testng.SuiteRunner.runSequentially(SuiteRunner.java:371)
at org.testng.SuiteRunner.privateRun(SuiteRunner.java:332)
at org.testng.SuiteRunner.run(SuiteRunner.java:276)
at org.testng.SuiteRunnerWorker.runSuite(SuiteRunnerWorker.java:53)
at org.testng.SuiteRunnerWorker.run(SuiteRunnerWorker.java:96)
at org.testng.TestNG.runSuitesSequentially(TestNG.java:1212)
at org.testng.TestNG.runSuitesLocally(TestNG.java:1134)
at org.testng.TestNG.runSuites(TestNG.java:1063)
at org.testng.TestNG.run(TestNG.java:1031)
at org.testng.remote.AbstractRemoteTestNG.run(AbstractRemoteTestNG.java:115)
at org.testng.remote.RemoteTestNG.initAndRun(RemoteTestNG.java:251)
at org.testng.remote.RemoteTestNG.main(RemoteTestNG.java:77)
]]>
    </error>
  </testcase> <!-- TestSelect_selectby_MaHD_MASP_Fail -->
  <system-out/>
</testsuite> <!-- DAO_Test.HoaDonChiTietDAO_Test -->
