<?xml version="1.0" encoding="UTF-8"?>
<!-- Generated by org.testng.reporters.JUnitReportReporter -->
<testsuite hostname="KoBietLun" failures="0" tests="18" name="DAO_Test.NhanVienDAOTest" time="1.038" errors="7" timestamp="2024-04-12T16:34:11 ICT" skipped="0">
  <testcase classname="DAO_Test.NhanVienDAOTest" name="insertTest_NullNVHoTen_Failed" time="0.045">
    <error message="
Method NhanVienDAOTest.insertTest_NullNVHoTen_Failed()[pri:0, instance:DAO_Test.NhanVienDAOTest@10aa41f2] should have thrown an exception of type class com.microsoft.sqlserver.jdbc.SQLServerException" type="org.testng.TestException">
      <![CDATA[org.testng.TestException: 
Method NhanVienDAOTest.insertTest_NullNVHoTen_Failed()[pri:0, instance:DAO_Test.NhanVienDAOTest@10aa41f2] should have thrown an exception of type class com.microsoft.sqlserver.jdbc.SQLServerException
at org.testng.internal.ExpectedExceptionsHolder.noException(ExpectedExceptionsHolder.java:82)
at org.testng.internal.TestInvoker.considerExceptions(TestInvoker.java:749)
at org.testng.internal.TestInvoker.invokeMethod(TestInvoker.java:634)
at org.testng.internal.TestInvoker.invokeTestMethod(TestInvoker.java:173)
at org.testng.internal.MethodRunner.runInSequence(MethodRunner.java:46)
at org.testng.internal.TestInvoker$MethodInvocationAgent.invoke(TestInvoker.java:824)
at org.testng.internal.TestInvoker.invokeTestMethods(TestInvoker.java:146)
at org.testng.internal.TestMethodWorker.invokeTestMethods(TestMethodWorker.java:146)
at org.testng.internal.TestMethodWorker.run(TestMethodWorker.java:128)
at java.base/java.util.ArrayList.forEach(ArrayList.java:1511)
at org.testng.TestRunner.privateRun(TestRunner.java:794)
at org.testng.TestRunner.run(TestRunner.java:596)
at org.testng.SuiteRunner.runTest(SuiteRunner.java:377)
at org.testng.SuiteRunner.runSequentially(SuiteRunner.java:371)
at org.testng.SuiteRunner.privateRun(SuiteRunner.java:332)
at org.testng.SuiteRunner.run(SuiteRunner.java:276)
at org.testng.SuiteRunnerWorker.runSuite(SuiteRunnerWorker.java:53)
at org.testng.SuiteRunnerWorker.run(SuiteRunnerWorker.java:96)
at org.testng.TestNG.runSuitesSequentially(TestNG.java:1212)
at org.testng.TestNG.runSuitesLocally(TestNG.java:1134)
at org.testng.TestNG.runSuites(TestNG.java:1063)
at org.testng.TestNG.run(TestNG.java:1031)
at org.testng.remote.AbstractRemoteTestNG.run(AbstractRemoteTestNG.java:115)
at org.testng.remote.RemoteTestNG.initAndRun(RemoteTestNG.java:251)
at org.testng.remote.RemoteTestNG.main(RemoteTestNG.java:77)
]]>
    </error>
  </testcase> <!-- insertTest_NullNVHoTen_Failed -->
  <system-out/>
  <testcase classname="DAO_Test.NhanVienDAOTest" name="updateTest_NullNVHoTen_Failed" time="0.046">
    <error message="
Method NhanVienDAOTest.updateTest_NullNVHoTen_Failed()[pri:0, instance:DAO_Test.NhanVienDAOTest@10aa41f2] should have thrown an exception of type class com.microsoft.sqlserver.jdbc.SQLServerException" type="org.testng.TestException">
      <![CDATA[org.testng.TestException: 
Method NhanVienDAOTest.updateTest_NullNVHoTen_Failed()[pri:0, instance:DAO_Test.NhanVienDAOTest@10aa41f2] should have thrown an exception of type class com.microsoft.sqlserver.jdbc.SQLServerException
at org.testng.internal.ExpectedExceptionsHolder.noException(ExpectedExceptionsHolder.java:82)
at org.testng.internal.TestInvoker.considerExceptions(TestInvoker.java:749)
at org.testng.internal.TestInvoker.invokeMethod(TestInvoker.java:634)
at org.testng.internal.TestInvoker.invokeTestMethod(TestInvoker.java:173)
at org.testng.internal.MethodRunner.runInSequence(MethodRunner.java:46)
at org.testng.internal.TestInvoker$MethodInvocationAgent.invoke(TestInvoker.java:824)
at org.testng.internal.TestInvoker.invokeTestMethods(TestInvoker.java:146)
at org.testng.internal.TestMethodWorker.invokeTestMethods(TestMethodWorker.java:146)
at org.testng.internal.TestMethodWorker.run(TestMethodWorker.java:128)
at java.base/java.util.ArrayList.forEach(ArrayList.java:1511)
at org.testng.TestRunner.privateRun(TestRunner.java:794)
at org.testng.TestRunner.run(TestRunner.java:596)
at org.testng.SuiteRunner.runTest(SuiteRunner.java:377)
at org.testng.SuiteRunner.runSequentially(SuiteRunner.java:371)
at org.testng.SuiteRunner.privateRun(SuiteRunner.java:332)
at org.testng.SuiteRunner.run(SuiteRunner.java:276)
at org.testng.SuiteRunnerWorker.runSuite(SuiteRunnerWorker.java:53)
at org.testng.SuiteRunnerWorker.run(SuiteRunnerWorker.java:96)
at org.testng.TestNG.runSuitesSequentially(TestNG.java:1212)
at org.testng.TestNG.runSuitesLocally(TestNG.java:1134)
at org.testng.TestNG.runSuites(TestNG.java:1063)
at org.testng.TestNG.run(TestNG.java:1031)
at org.testng.remote.AbstractRemoteTestNG.run(AbstractRemoteTestNG.java:115)
at org.testng.remote.RemoteTestNG.initAndRun(RemoteTestNG.java:251)
at org.testng.remote.RemoteTestNG.main(RemoteTestNG.java:77)
]]>
    </error>
  </testcase> <!-- updateTest_NullNVHoTen_Failed -->
  <system-out/>
  <testcase classname="DAO_Test.NhanVienDAOTest" name="updateTest_NullNVID_Failed" time="0.054"/>
  <system-out/>
  <testcase classname="DAO_Test.NhanVienDAOTest" name="insertTest_NullNVDiaChi_Failed" time="0.050"/>
  <system-out/>
  <testcase classname="DAO_Test.NhanVienDAOTest" name="updateTest_NullNVEmail_Passed" time="0.039"/>
  <system-out/>
  <testcase classname="DAO_Test.NhanVienDAOTest" name="SelectByIDTest_Failed" time="0.288"/>
  <system-out/>
  <testcase classname="DAO_Test.NhanVienDAOTest" name="SelectByIDTest_Passed" time="0.030"/>
  <system-out/>
  <testcase classname="DAO_Test.NhanVienDAOTest" name="insertTest_NullNVID_Failed" time="0.047">
    <error message="
Method NhanVienDAOTest.insertTest_NullNVID_Failed()[pri:0, instance:DAO_Test.NhanVienDAOTest@10aa41f2] should have thrown an exception of type class com.microsoft.sqlserver.jdbc.SQLServerException" type="org.testng.TestException">
      <![CDATA[org.testng.TestException: 
Method NhanVienDAOTest.insertTest_NullNVID_Failed()[pri:0, instance:DAO_Test.NhanVienDAOTest@10aa41f2] should have thrown an exception of type class com.microsoft.sqlserver.jdbc.SQLServerException
at org.testng.internal.ExpectedExceptionsHolder.noException(ExpectedExceptionsHolder.java:82)
at org.testng.internal.TestInvoker.considerExceptions(TestInvoker.java:749)
at org.testng.internal.TestInvoker.invokeMethod(TestInvoker.java:634)
at org.testng.internal.TestInvoker.invokeTestMethod(TestInvoker.java:173)
at org.testng.internal.MethodRunner.runInSequence(MethodRunner.java:46)
at org.testng.internal.TestInvoker$MethodInvocationAgent.invoke(TestInvoker.java:824)
at org.testng.internal.TestInvoker.invokeTestMethods(TestInvoker.java:146)
at org.testng.internal.TestMethodWorker.invokeTestMethods(TestMethodWorker.java:146)
at org.testng.internal.TestMethodWorker.run(TestMethodWorker.java:128)
at java.base/java.util.ArrayList.forEach(ArrayList.java:1511)
at org.testng.TestRunner.privateRun(TestRunner.java:794)
at org.testng.TestRunner.run(TestRunner.java:596)
at org.testng.SuiteRunner.runTest(SuiteRunner.java:377)
at org.testng.SuiteRunner.runSequentially(SuiteRunner.java:371)
at org.testng.SuiteRunner.privateRun(SuiteRunner.java:332)
at org.testng.SuiteRunner.run(SuiteRunner.java:276)
at org.testng.SuiteRunnerWorker.runSuite(SuiteRunnerWorker.java:53)
at org.testng.SuiteRunnerWorker.run(SuiteRunnerWorker.java:96)
at org.testng.TestNG.runSuitesSequentially(TestNG.java:1212)
at org.testng.TestNG.runSuitesLocally(TestNG.java:1134)
at org.testng.TestNG.runSuites(TestNG.java:1063)
at org.testng.TestNG.run(TestNG.java:1031)
at org.testng.remote.AbstractRemoteTestNG.run(AbstractRemoteTestNG.java:115)
at org.testng.remote.RemoteTestNG.initAndRun(RemoteTestNG.java:251)
at org.testng.remote.RemoteTestNG.main(RemoteTestNG.java:77)
]]>
    </error>
  </testcase> <!-- insertTest_NullNVID_Failed -->
  <system-out/>
  <testcase classname="DAO_Test.NhanVienDAOTest" name="insertTest_NullNVSoDienThoai_Failed" time="0.049">
    <error message="
Method NhanVienDAOTest.insertTest_NullNVSoDienThoai_Failed()[pri:0, instance:DAO_Test.NhanVienDAOTest@10aa41f2] should have thrown an exception of type class com.microsoft.sqlserver.jdbc.SQLServerException" type="org.testng.TestException">
      <![CDATA[org.testng.TestException: 
Method NhanVienDAOTest.insertTest_NullNVSoDienThoai_Failed()[pri:0, instance:DAO_Test.NhanVienDAOTest@10aa41f2] should have thrown an exception of type class com.microsoft.sqlserver.jdbc.SQLServerException
at org.testng.internal.ExpectedExceptionsHolder.noException(ExpectedExceptionsHolder.java:82)
at org.testng.internal.TestInvoker.considerExceptions(TestInvoker.java:749)
at org.testng.internal.TestInvoker.invokeMethod(TestInvoker.java:634)
at org.testng.internal.TestInvoker.invokeTestMethod(TestInvoker.java:173)
at org.testng.internal.MethodRunner.runInSequence(MethodRunner.java:46)
at org.testng.internal.TestInvoker$MethodInvocationAgent.invoke(TestInvoker.java:824)
at org.testng.internal.TestInvoker.invokeTestMethods(TestInvoker.java:146)
at org.testng.internal.TestMethodWorker.invokeTestMethods(TestMethodWorker.java:146)
at org.testng.internal.TestMethodWorker.run(TestMethodWorker.java:128)
at java.base/java.util.ArrayList.forEach(ArrayList.java:1511)
at org.testng.TestRunner.privateRun(TestRunner.java:794)
at org.testng.TestRunner.run(TestRunner.java:596)
at org.testng.SuiteRunner.runTest(SuiteRunner.java:377)
at org.testng.SuiteRunner.runSequentially(SuiteRunner.java:371)
at org.testng.SuiteRunner.privateRun(SuiteRunner.java:332)
at org.testng.SuiteRunner.run(SuiteRunner.java:276)
at org.testng.SuiteRunnerWorker.runSuite(SuiteRunnerWorker.java:53)
at org.testng.SuiteRunnerWorker.run(SuiteRunnerWorker.java:96)
at org.testng.TestNG.runSuitesSequentially(TestNG.java:1212)
at org.testng.TestNG.runSuitesLocally(TestNG.java:1134)
at org.testng.TestNG.runSuites(TestNG.java:1063)
at org.testng.TestNG.run(TestNG.java:1031)
at org.testng.remote.AbstractRemoteTestNG.run(AbstractRemoteTestNG.java:115)
at org.testng.remote.RemoteTestNG.initAndRun(RemoteTestNG.java:251)
at org.testng.remote.RemoteTestNG.main(RemoteTestNG.java:77)
]]>
    </error>
  </testcase> <!-- insertTest_NullNVSoDienThoai_Failed -->
  <system-out/>
  <testcase classname="DAO_Test.NhanVienDAOTest" name="insertTest_NullAll_Failed" time="0.051">
    <error message="
Method NhanVienDAOTest.insertTest_NullAll_Failed()[pri:0, instance:DAO_Test.NhanVienDAOTest@10aa41f2] should have thrown an exception of type class java.sql.SQLException" type="org.testng.TestException">
      <![CDATA[org.testng.TestException: 
Method NhanVienDAOTest.insertTest_NullAll_Failed()[pri:0, instance:DAO_Test.NhanVienDAOTest@10aa41f2] should have thrown an exception of type class java.sql.SQLException
at org.testng.internal.ExpectedExceptionsHolder.noException(ExpectedExceptionsHolder.java:82)
at org.testng.internal.TestInvoker.considerExceptions(TestInvoker.java:749)
at org.testng.internal.TestInvoker.invokeMethod(TestInvoker.java:634)
at org.testng.internal.TestInvoker.invokeTestMethod(TestInvoker.java:173)
at org.testng.internal.MethodRunner.runInSequence(MethodRunner.java:46)
at org.testng.internal.TestInvoker$MethodInvocationAgent.invoke(TestInvoker.java:824)
at org.testng.internal.TestInvoker.invokeTestMethods(TestInvoker.java:146)
at org.testng.internal.TestMethodWorker.invokeTestMethods(TestMethodWorker.java:146)
at org.testng.internal.TestMethodWorker.run(TestMethodWorker.java:128)
at java.base/java.util.ArrayList.forEach(ArrayList.java:1511)
at org.testng.TestRunner.privateRun(TestRunner.java:794)
at org.testng.TestRunner.run(TestRunner.java:596)
at org.testng.SuiteRunner.runTest(SuiteRunner.java:377)
at org.testng.SuiteRunner.runSequentially(SuiteRunner.java:371)
at org.testng.SuiteRunner.privateRun(SuiteRunner.java:332)
at org.testng.SuiteRunner.run(SuiteRunner.java:276)
at org.testng.SuiteRunnerWorker.runSuite(SuiteRunnerWorker.java:53)
at org.testng.SuiteRunnerWorker.run(SuiteRunnerWorker.java:96)
at org.testng.TestNG.runSuitesSequentially(TestNG.java:1212)
at org.testng.TestNG.runSuitesLocally(TestNG.java:1134)
at org.testng.TestNG.runSuites(TestNG.java:1063)
at org.testng.TestNG.run(TestNG.java:1031)
at org.testng.remote.AbstractRemoteTestNG.run(AbstractRemoteTestNG.java:115)
at org.testng.remote.RemoteTestNG.initAndRun(RemoteTestNG.java:251)
at org.testng.remote.RemoteTestNG.main(RemoteTestNG.java:77)
]]>
    </error>
  </testcase> <!-- insertTest_NullAll_Failed -->
  <system-out/>
  <testcase classname="DAO_Test.NhanVienDAOTest" name="deleteTest_Passed" time="0.046"/>
  <system-out/>
  <testcase classname="DAO_Test.NhanVienDAOTest" name="updateTest_NullNVDiaChi_Passed" time="0.043"/>
  <system-out/>
  <testcase classname="DAO_Test.NhanVienDAOTest" name="selectAllTest_Passed" time="0.020"/>
  <system-out/>
  <testcase classname="DAO_Test.NhanVienDAOTest" name="insertTest_Passed" time="0.073"/>
  <system-out/>
  <testcase classname="DAO_Test.NhanVienDAOTest" name="insertTest_NullNVEmail_Failed" time="0.041">
    <error message="
Method NhanVienDAOTest.insertTest_NullNVEmail_Failed()[pri:0, instance:DAO_Test.NhanVienDAOTest@10aa41f2] should have thrown an exception of type class com.microsoft.sqlserver.jdbc.SQLServerException" type="org.testng.TestException">
      <![CDATA[org.testng.TestException: 
Method NhanVienDAOTest.insertTest_NullNVEmail_Failed()[pri:0, instance:DAO_Test.NhanVienDAOTest@10aa41f2] should have thrown an exception of type class com.microsoft.sqlserver.jdbc.SQLServerException
at org.testng.internal.ExpectedExceptionsHolder.noException(ExpectedExceptionsHolder.java:82)
at org.testng.internal.TestInvoker.considerExceptions(TestInvoker.java:749)
at org.testng.internal.TestInvoker.invokeMethod(TestInvoker.java:634)
at org.testng.internal.TestInvoker.invokeTestMethod(TestInvoker.java:173)
at org.testng.internal.MethodRunner.runInSequence(MethodRunner.java:46)
at org.testng.internal.TestInvoker$MethodInvocationAgent.invoke(TestInvoker.java:824)
at org.testng.internal.TestInvoker.invokeTestMethods(TestInvoker.java:146)
at org.testng.internal.TestMethodWorker.invokeTestMethods(TestMethodWorker.java:146)
at org.testng.internal.TestMethodWorker.run(TestMethodWorker.java:128)
at java.base/java.util.ArrayList.forEach(ArrayList.java:1511)
at org.testng.TestRunner.privateRun(TestRunner.java:794)
at org.testng.TestRunner.run(TestRunner.java:596)
at org.testng.SuiteRunner.runTest(SuiteRunner.java:377)
at org.testng.SuiteRunner.runSequentially(SuiteRunner.java:371)
at org.testng.SuiteRunner.privateRun(SuiteRunner.java:332)
at org.testng.SuiteRunner.run(SuiteRunner.java:276)
at org.testng.SuiteRunnerWorker.runSuite(SuiteRunnerWorker.java:53)
at org.testng.SuiteRunnerWorker.run(SuiteRunnerWorker.java:96)
at org.testng.TestNG.runSuitesSequentially(TestNG.java:1212)
at org.testng.TestNG.runSuitesLocally(TestNG.java:1134)
at org.testng.TestNG.runSuites(TestNG.java:1063)
at org.testng.TestNG.run(TestNG.java:1031)
at org.testng.remote.AbstractRemoteTestNG.run(AbstractRemoteTestNG.java:115)
at org.testng.remote.RemoteTestNG.initAndRun(RemoteTestNG.java:251)
at org.testng.remote.RemoteTestNG.main(RemoteTestNG.java:77)
]]>
    </error>
  </testcase> <!-- insertTest_NullNVEmail_Failed -->
  <system-out/>
  <testcase classname="DAO_Test.NhanVienDAOTest" name="updateTest_Passed" time="0.037"/>
  <system-out/>
  <testcase classname="DAO_Test.NhanVienDAOTest" name="insertTest_NullNVMatKhau_Failed" time="0.042">
    <error message="
Method NhanVienDAOTest.insertTest_NullNVMatKhau_Failed()[pri:0, instance:DAO_Test.NhanVienDAOTest@10aa41f2] should have thrown an exception of type class com.microsoft.sqlserver.jdbc.SQLServerException" type="org.testng.TestException">
      <![CDATA[org.testng.TestException: 
Method NhanVienDAOTest.insertTest_NullNVMatKhau_Failed()[pri:0, instance:DAO_Test.NhanVienDAOTest@10aa41f2] should have thrown an exception of type class com.microsoft.sqlserver.jdbc.SQLServerException
at org.testng.internal.ExpectedExceptionsHolder.noException(ExpectedExceptionsHolder.java:82)
at org.testng.internal.TestInvoker.considerExceptions(TestInvoker.java:749)
at org.testng.internal.TestInvoker.invokeMethod(TestInvoker.java:634)
at org.testng.internal.TestInvoker.invokeTestMethod(TestInvoker.java:173)
at org.testng.internal.MethodRunner.runInSequence(MethodRunner.java:46)
at org.testng.internal.TestInvoker$MethodInvocationAgent.invoke(TestInvoker.java:824)
at org.testng.internal.TestInvoker.invokeTestMethods(TestInvoker.java:146)
at org.testng.internal.TestMethodWorker.invokeTestMethods(TestMethodWorker.java:146)
at org.testng.internal.TestMethodWorker.run(TestMethodWorker.java:128)
at java.base/java.util.ArrayList.forEach(ArrayList.java:1511)
at org.testng.TestRunner.privateRun(TestRunner.java:794)
at org.testng.TestRunner.run(TestRunner.java:596)
at org.testng.SuiteRunner.runTest(SuiteRunner.java:377)
at org.testng.SuiteRunner.runSequentially(SuiteRunner.java:371)
at org.testng.SuiteRunner.privateRun(SuiteRunner.java:332)
at org.testng.SuiteRunner.run(SuiteRunner.java:276)
at org.testng.SuiteRunnerWorker.runSuite(SuiteRunnerWorker.java:53)
at org.testng.SuiteRunnerWorker.run(SuiteRunnerWorker.java:96)
at org.testng.TestNG.runSuitesSequentially(TestNG.java:1212)
at org.testng.TestNG.runSuitesLocally(TestNG.java:1134)
at org.testng.TestNG.runSuites(TestNG.java:1063)
at org.testng.TestNG.run(TestNG.java:1031)
at org.testng.remote.AbstractRemoteTestNG.run(AbstractRemoteTestNG.java:115)
at org.testng.remote.RemoteTestNG.initAndRun(RemoteTestNG.java:251)
at org.testng.remote.RemoteTestNG.main(RemoteTestNG.java:77)
]]>
    </error>
  </testcase> <!-- insertTest_NullNVMatKhau_Failed -->
  <system-out/>
  <testcase classname="DAO_Test.NhanVienDAOTest" name="updateTest_NullNVSDT_Passed" time="0.037"/>
  <system-out/>
</testsuite> <!-- DAO_Test.NhanVienDAOTest -->
