<?xml version="1.0" encoding="UTF-8"?>
<!-- Generated by org.testng.reporters.JUnitReportReporter -->
<testsuite hostname="KoBietLun" failures="1" tests="26" name="DAO_Test.HoaDonDAO_Test" time="2.010" errors="14" timestamp="2024-04-12T15:08:21 ICT" skipped="0">
  <testcase classname="DAO_Test.HoaDonDAO_Test" name="TestSelect_ByID_Fail" time="0.037">
    <error message="
Method HoaDonDAO_Test.TestSelect_ByID_Fail()[pri:0, instance:DAO_Test.HoaDonDAO_Test@6ab778a] should have thrown an exception of type class com.microsoft.sqlserver.jdbc.SQLServerException" type="org.testng.TestException">
      <![CDATA[org.testng.TestException: 
Method HoaDonDAO_Test.TestSelect_ByID_Fail()[pri:0, instance:DAO_Test.HoaDonDAO_Test@6ab778a] should have thrown an exception of type class com.microsoft.sqlserver.jdbc.SQLServerException
at org.testng.internal.ExpectedExceptionsHolder.noException(ExpectedExceptionsHolder.java:82)
at org.testng.internal.TestInvoker.considerExceptions(TestInvoker.java:749)
at org.testng.internal.TestInvoker.invokeMethod(TestInvoker.java:634)
at org.testng.internal.TestInvoker.invokeTestMethod(TestInvoker.java:173)
at org.testng.internal.MethodRunner.runInSequence(MethodRunner.java:46)
at org.testng.internal.TestInvoker$MethodInvocationAgent.invoke(TestInvoker.java:824)
at org.testng.internal.TestInvoker.invokeTestMethods(TestInvoker.java:146)
at org.testng.internal.TestMethodWorker.invokeTestMethods(TestMethodWorker.java:146)
at org.testng.internal.TestMethodWorker.run(TestMethodWorker.java:128)
at java.base/java.util.ArrayList.forEach(ArrayList.java:1511)
at org.testng.TestRunner.privateRun(TestRunner.java:794)
at org.testng.TestRunner.run(TestRunner.java:596)
at org.testng.SuiteRunner.runTest(SuiteRunner.java:377)
at org.testng.SuiteRunner.runSequentially(SuiteRunner.java:371)
at org.testng.SuiteRunner.privateRun(SuiteRunner.java:332)
at org.testng.SuiteRunner.run(SuiteRunner.java:276)
at org.testng.SuiteRunnerWorker.runSuite(SuiteRunnerWorker.java:53)
at org.testng.SuiteRunnerWorker.run(SuiteRunnerWorker.java:96)
at org.testng.TestNG.runSuitesSequentially(TestNG.java:1212)
at org.testng.TestNG.runSuitesLocally(TestNG.java:1134)
at org.testng.TestNG.runSuites(TestNG.java:1063)
at org.testng.TestNG.run(TestNG.java:1031)
at org.testng.remote.AbstractRemoteTestNG.run(AbstractRemoteTestNG.java:115)
at org.testng.remote.RemoteTestNG.initAndRun(RemoteTestNG.java:251)
at org.testng.remote.RemoteTestNG.main(RemoteTestNG.java:77)
]]>
    </error>
  </testcase> <!-- TestSelect_ByID_Fail -->
  <system-out/>
  <testcase classname="DAO_Test.HoaDonDAO_Test" name="TestInsert_NullAll_Fail" time="0.080">
    <error message="
Method HoaDonDAO_Test.TestInsert_NullAll_Fail()[pri:0, instance:DAO_Test.HoaDonDAO_Test@6ab778a] should have thrown an exception of type class com.microsoft.sqlserver.jdbc.SQLServerException" type="org.testng.TestException">
      <![CDATA[org.testng.TestException: 
Method HoaDonDAO_Test.TestInsert_NullAll_Fail()[pri:0, instance:DAO_Test.HoaDonDAO_Test@6ab778a] should have thrown an exception of type class com.microsoft.sqlserver.jdbc.SQLServerException
at org.testng.internal.ExpectedExceptionsHolder.noException(ExpectedExceptionsHolder.java:82)
at org.testng.internal.TestInvoker.considerExceptions(TestInvoker.java:749)
at org.testng.internal.TestInvoker.invokeMethod(TestInvoker.java:634)
at org.testng.internal.TestInvoker.invokeTestMethod(TestInvoker.java:173)
at org.testng.internal.MethodRunner.runInSequence(MethodRunner.java:46)
at org.testng.internal.TestInvoker$MethodInvocationAgent.invoke(TestInvoker.java:824)
at org.testng.internal.TestInvoker.invokeTestMethods(TestInvoker.java:146)
at org.testng.internal.TestMethodWorker.invokeTestMethods(TestMethodWorker.java:146)
at org.testng.internal.TestMethodWorker.run(TestMethodWorker.java:128)
at java.base/java.util.ArrayList.forEach(ArrayList.java:1511)
at org.testng.TestRunner.privateRun(TestRunner.java:794)
at org.testng.TestRunner.run(TestRunner.java:596)
at org.testng.SuiteRunner.runTest(SuiteRunner.java:377)
at org.testng.SuiteRunner.runSequentially(SuiteRunner.java:371)
at org.testng.SuiteRunner.privateRun(SuiteRunner.java:332)
at org.testng.SuiteRunner.run(SuiteRunner.java:276)
at org.testng.SuiteRunnerWorker.runSuite(SuiteRunnerWorker.java:53)
at org.testng.SuiteRunnerWorker.run(SuiteRunnerWorker.java:96)
at org.testng.TestNG.runSuitesSequentially(TestNG.java:1212)
at org.testng.TestNG.runSuitesLocally(TestNG.java:1134)
at org.testng.TestNG.runSuites(TestNG.java:1063)
at org.testng.TestNG.run(TestNG.java:1031)
at org.testng.remote.AbstractRemoteTestNG.run(AbstractRemoteTestNG.java:115)
at org.testng.remote.RemoteTestNG.initAndRun(RemoteTestNG.java:251)
at org.testng.remote.RemoteTestNG.main(RemoteTestNG.java:77)
]]>
    </error>
  </testcase> <!-- TestInsert_NullAll_Fail -->
  <system-out/>
  <testcase classname="DAO_Test.HoaDonDAO_Test" name="TestUpdate_GiamGia_Pass" time="0.056"/>
  <system-out/>
  <testcase classname="DAO_Test.HoaDonDAO_Test" name="TestUpdate_NgayTao_Pass" time="0.049"/>
  <system-out/>
  <testcase classname="DAO_Test.HoaDonDAO_Test" name="TestInsert_NullTenKhachHang_Fail" time="0.064">
    <error message="
Method HoaDonDAO_Test.TestInsert_NullTenKhachHang_Fail()[pri:0, instance:DAO_Test.HoaDonDAO_Test@6ab778a] should have thrown an exception of type class com.microsoft.sqlserver.jdbc.SQLServerException" type="org.testng.TestException">
      <![CDATA[org.testng.TestException: 
Method HoaDonDAO_Test.TestInsert_NullTenKhachHang_Fail()[pri:0, instance:DAO_Test.HoaDonDAO_Test@6ab778a] should have thrown an exception of type class com.microsoft.sqlserver.jdbc.SQLServerException
at org.testng.internal.ExpectedExceptionsHolder.noException(ExpectedExceptionsHolder.java:82)
at org.testng.internal.TestInvoker.considerExceptions(TestInvoker.java:749)
at org.testng.internal.TestInvoker.invokeMethod(TestInvoker.java:634)
at org.testng.internal.TestInvoker.invokeTestMethod(TestInvoker.java:173)
at org.testng.internal.MethodRunner.runInSequence(MethodRunner.java:46)
at org.testng.internal.TestInvoker$MethodInvocationAgent.invoke(TestInvoker.java:824)
at org.testng.internal.TestInvoker.invokeTestMethods(TestInvoker.java:146)
at org.testng.internal.TestMethodWorker.invokeTestMethods(TestMethodWorker.java:146)
at org.testng.internal.TestMethodWorker.run(TestMethodWorker.java:128)
at java.base/java.util.ArrayList.forEach(ArrayList.java:1511)
at org.testng.TestRunner.privateRun(TestRunner.java:794)
at org.testng.TestRunner.run(TestRunner.java:596)
at org.testng.SuiteRunner.runTest(SuiteRunner.java:377)
at org.testng.SuiteRunner.runSequentially(SuiteRunner.java:371)
at org.testng.SuiteRunner.privateRun(SuiteRunner.java:332)
at org.testng.SuiteRunner.run(SuiteRunner.java:276)
at org.testng.SuiteRunnerWorker.runSuite(SuiteRunnerWorker.java:53)
at org.testng.SuiteRunnerWorker.run(SuiteRunnerWorker.java:96)
at org.testng.TestNG.runSuitesSequentially(TestNG.java:1212)
at org.testng.TestNG.runSuitesLocally(TestNG.java:1134)
at org.testng.TestNG.runSuites(TestNG.java:1063)
at org.testng.TestNG.run(TestNG.java:1031)
at org.testng.remote.AbstractRemoteTestNG.run(AbstractRemoteTestNG.java:115)
at org.testng.remote.RemoteTestNG.initAndRun(RemoteTestNG.java:251)
at org.testng.remote.RemoteTestNG.main(RemoteTestNG.java:77)
]]>
    </error>
  </testcase> <!-- TestInsert_NullTenKhachHang_Fail -->
  <system-out/>
  <testcase classname="DAO_Test.HoaDonDAO_Test" name="TestUpdate_All_Pass" time="0.082">
    <error message="
Method HoaDonDAO_Test.TestUpdate_All_Pass()[pri:0, instance:DAO_Test.HoaDonDAO_Test@6ab778a] should have thrown an exception of type class com.microsoft.sqlserver.jdbc.SQLServerException" type="org.testng.TestException">
      <![CDATA[org.testng.TestException: 
Method HoaDonDAO_Test.TestUpdate_All_Pass()[pri:0, instance:DAO_Test.HoaDonDAO_Test@6ab778a] should have thrown an exception of type class com.microsoft.sqlserver.jdbc.SQLServerException
at org.testng.internal.ExpectedExceptionsHolder.noException(ExpectedExceptionsHolder.java:82)
at org.testng.internal.TestInvoker.considerExceptions(TestInvoker.java:749)
at org.testng.internal.TestInvoker.invokeMethod(TestInvoker.java:634)
at org.testng.internal.TestInvoker.invokeTestMethod(TestInvoker.java:173)
at org.testng.internal.MethodRunner.runInSequence(MethodRunner.java:46)
at org.testng.internal.TestInvoker$MethodInvocationAgent.invoke(TestInvoker.java:824)
at org.testng.internal.TestInvoker.invokeTestMethods(TestInvoker.java:146)
at org.testng.internal.TestMethodWorker.invokeTestMethods(TestMethodWorker.java:146)
at org.testng.internal.TestMethodWorker.run(TestMethodWorker.java:128)
at java.base/java.util.ArrayList.forEach(ArrayList.java:1511)
at org.testng.TestRunner.privateRun(TestRunner.java:794)
at org.testng.TestRunner.run(TestRunner.java:596)
at org.testng.SuiteRunner.runTest(SuiteRunner.java:377)
at org.testng.SuiteRunner.runSequentially(SuiteRunner.java:371)
at org.testng.SuiteRunner.privateRun(SuiteRunner.java:332)
at org.testng.SuiteRunner.run(SuiteRunner.java:276)
at org.testng.SuiteRunnerWorker.runSuite(SuiteRunnerWorker.java:53)
at org.testng.SuiteRunnerWorker.run(SuiteRunnerWorker.java:96)
at org.testng.TestNG.runSuitesSequentially(TestNG.java:1212)
at org.testng.TestNG.runSuitesLocally(TestNG.java:1134)
at org.testng.TestNG.runSuites(TestNG.java:1063)
at org.testng.TestNG.run(TestNG.java:1031)
at org.testng.remote.AbstractRemoteTestNG.run(AbstractRemoteTestNG.java:115)
at org.testng.remote.RemoteTestNG.initAndRun(RemoteTestNG.java:251)
at org.testng.remote.RemoteTestNG.main(RemoteTestNG.java:77)
]]>
    </error>
  </testcase> <!-- TestUpdate_All_Pass -->
  <system-out/>
  <testcase classname="DAO_Test.HoaDonDAO_Test" name="TestSelect_BySQL_Fail" time="0.033">
    <error message="
Expected exception of type class com.microsoft.sqlserver.jdbc.SQLServerException but got java.lang.AssertionError: expected [null] but found [[]]" type="org.testng.TestException">
      <![CDATA[org.testng.TestException: 
Expected exception of type class com.microsoft.sqlserver.jdbc.SQLServerException but got java.lang.AssertionError: expected [null] but found [[]]
at org.testng.internal.ExpectedExceptionsHolder.wrongException(ExpectedExceptionsHolder.java:68)
at org.testng.internal.TestInvoker.considerExceptions(TestInvoker.java:739)
at org.testng.internal.TestInvoker.invokeMethod(TestInvoker.java:634)
at org.testng.internal.TestInvoker.invokeTestMethod(TestInvoker.java:173)
at org.testng.internal.MethodRunner.runInSequence(MethodRunner.java:46)
at org.testng.internal.TestInvoker$MethodInvocationAgent.invoke(TestInvoker.java:824)
at org.testng.internal.TestInvoker.invokeTestMethods(TestInvoker.java:146)
at org.testng.internal.TestMethodWorker.invokeTestMethods(TestMethodWorker.java:146)
at org.testng.internal.TestMethodWorker.run(TestMethodWorker.java:128)
at java.base/java.util.ArrayList.forEach(ArrayList.java:1511)
at org.testng.TestRunner.privateRun(TestRunner.java:794)
at org.testng.TestRunner.run(TestRunner.java:596)
at org.testng.SuiteRunner.runTest(SuiteRunner.java:377)
at org.testng.SuiteRunner.runSequentially(SuiteRunner.java:371)
at org.testng.SuiteRunner.privateRun(SuiteRunner.java:332)
at org.testng.SuiteRunner.run(SuiteRunner.java:276)
at org.testng.SuiteRunnerWorker.runSuite(SuiteRunnerWorker.java:53)
at org.testng.SuiteRunnerWorker.run(SuiteRunnerWorker.java:96)
at org.testng.TestNG.runSuitesSequentially(TestNG.java:1212)
at org.testng.TestNG.runSuitesLocally(TestNG.java:1134)
at org.testng.TestNG.runSuites(TestNG.java:1063)
at org.testng.TestNG.run(TestNG.java:1031)
at org.testng.remote.AbstractRemoteTestNG.run(AbstractRemoteTestNG.java:115)
at org.testng.remote.RemoteTestNG.initAndRun(RemoteTestNG.java:251)
at org.testng.remote.RemoteTestNG.main(RemoteTestNG.java:77)
Caused by: java.lang.AssertionError: expected [null] but found [[]]
at org.testng.Assert.fail(Assert.java:99)
at org.testng.Assert.failNotSame(Assert.java:1033)
at org.testng.Assert.assertNull(Assert.java:965)
at org.testng.Assert.assertNull(Assert.java:953)
at DAO_Test.HoaDonDAO_Test.TestSelect_BySQL_Fail(HoaDonDAO_Test.java:299)
at java.base/jdk.internal.reflect.DirectMethodHandleAccessor.invoke(DirectMethodHandleAccessor.java:104)
at java.base/java.lang.reflect.Method.invoke(Method.java:578)
at org.testng.internal.MethodInvocationHelper.invokeMethod(MethodInvocationHelper.java:133)
at org.testng.internal.TestInvoker.invokeMethod(TestInvoker.java:598)
... 22 more
]]>
    </error>
  </testcase> <!-- TestSelect_BySQL_Fail -->
  <system-out/>
  <testcase classname="DAO_Test.HoaDonDAO_Test" name="TestInsert_Pass" time="0.003"/>
  <system-out/>
  <testcase classname="DAO_Test.HoaDonDAO_Test" name="TestUpdate_NullMaNV_Fail" time="0.075">
    <error message="
Method HoaDonDAO_Test.TestUpdate_NullMaNV_Fail()[pri:0, instance:DAO_Test.HoaDonDAO_Test@6ab778a] should have thrown an exception of type class com.microsoft.sqlserver.jdbc.SQLServerException" type="org.testng.TestException">
      <![CDATA[org.testng.TestException: 
Method HoaDonDAO_Test.TestUpdate_NullMaNV_Fail()[pri:0, instance:DAO_Test.HoaDonDAO_Test@6ab778a] should have thrown an exception of type class com.microsoft.sqlserver.jdbc.SQLServerException
at org.testng.internal.ExpectedExceptionsHolder.noException(ExpectedExceptionsHolder.java:82)
at org.testng.internal.TestInvoker.considerExceptions(TestInvoker.java:749)
at org.testng.internal.TestInvoker.invokeMethod(TestInvoker.java:634)
at org.testng.internal.TestInvoker.invokeTestMethod(TestInvoker.java:173)
at org.testng.internal.MethodRunner.runInSequence(MethodRunner.java:46)
at org.testng.internal.TestInvoker$MethodInvocationAgent.invoke(TestInvoker.java:824)
at org.testng.internal.TestInvoker.invokeTestMethods(TestInvoker.java:146)
at org.testng.internal.TestMethodWorker.invokeTestMethods(TestMethodWorker.java:146)
at org.testng.internal.TestMethodWorker.run(TestMethodWorker.java:128)
at java.base/java.util.ArrayList.forEach(ArrayList.java:1511)
at org.testng.TestRunner.privateRun(TestRunner.java:794)
at org.testng.TestRunner.run(TestRunner.java:596)
at org.testng.SuiteRunner.runTest(SuiteRunner.java:377)
at org.testng.SuiteRunner.runSequentially(SuiteRunner.java:371)
at org.testng.SuiteRunner.privateRun(SuiteRunner.java:332)
at org.testng.SuiteRunner.run(SuiteRunner.java:276)
at org.testng.SuiteRunnerWorker.runSuite(SuiteRunnerWorker.java:53)
at org.testng.SuiteRunnerWorker.run(SuiteRunnerWorker.java:96)
at org.testng.TestNG.runSuitesSequentially(TestNG.java:1212)
at org.testng.TestNG.runSuitesLocally(TestNG.java:1134)
at org.testng.TestNG.runSuites(TestNG.java:1063)
at org.testng.TestNG.run(TestNG.java:1031)
at org.testng.remote.AbstractRemoteTestNG.run(AbstractRemoteTestNG.java:115)
at org.testng.remote.RemoteTestNG.initAndRun(RemoteTestNG.java:251)
at org.testng.remote.RemoteTestNG.main(RemoteTestNG.java:77)
]]>
    </error>
  </testcase> <!-- TestUpdate_NullMaNV_Fail -->
  <system-out/>
  <testcase classname="DAO_Test.HoaDonDAO_Test" name="TestUpdate_dienThoai_Pass" time="0.051"/>
  <system-out/>
  <testcase classname="DAO_Test.HoaDonDAO_Test" name="TestUpdate_MaNV_Pass" time="0.058"/>
  <system-out/>
  <testcase classname="DAO_Test.HoaDonDAO_Test" name="TestDelete_Pass" time="0.134"/>
  <system-out/>
  <testcase classname="DAO_Test.HoaDonDAO_Test" name="TestInsert_NullHoTen_Fail" time="0.064">
    <error message="
Method HoaDonDAO_Test.TestInsert_NullHoTen_Fail()[pri:0, instance:DAO_Test.HoaDonDAO_Test@6ab778a] should have thrown an exception of type class com.microsoft.sqlserver.jdbc.SQLServerException" type="org.testng.TestException">
      <![CDATA[org.testng.TestException: 
Method HoaDonDAO_Test.TestInsert_NullHoTen_Fail()[pri:0, instance:DAO_Test.HoaDonDAO_Test@6ab778a] should have thrown an exception of type class com.microsoft.sqlserver.jdbc.SQLServerException
at org.testng.internal.ExpectedExceptionsHolder.noException(ExpectedExceptionsHolder.java:82)
at org.testng.internal.TestInvoker.considerExceptions(TestInvoker.java:749)
at org.testng.internal.TestInvoker.invokeMethod(TestInvoker.java:634)
at org.testng.internal.TestInvoker.invokeTestMethod(TestInvoker.java:173)
at org.testng.internal.MethodRunner.runInSequence(MethodRunner.java:46)
at org.testng.internal.TestInvoker$MethodInvocationAgent.invoke(TestInvoker.java:824)
at org.testng.internal.TestInvoker.invokeTestMethods(TestInvoker.java:146)
at org.testng.internal.TestMethodWorker.invokeTestMethods(TestMethodWorker.java:146)
at org.testng.internal.TestMethodWorker.run(TestMethodWorker.java:128)
at java.base/java.util.ArrayList.forEach(ArrayList.java:1511)
at org.testng.TestRunner.privateRun(TestRunner.java:794)
at org.testng.TestRunner.run(TestRunner.java:596)
at org.testng.SuiteRunner.runTest(SuiteRunner.java:377)
at org.testng.SuiteRunner.runSequentially(SuiteRunner.java:371)
at org.testng.SuiteRunner.privateRun(SuiteRunner.java:332)
at org.testng.SuiteRunner.run(SuiteRunner.java:276)
at org.testng.SuiteRunnerWorker.runSuite(SuiteRunnerWorker.java:53)
at org.testng.SuiteRunnerWorker.run(SuiteRunnerWorker.java:96)
at org.testng.TestNG.runSuitesSequentially(TestNG.java:1212)
at org.testng.TestNG.runSuitesLocally(TestNG.java:1134)
at org.testng.TestNG.runSuites(TestNG.java:1063)
at org.testng.TestNG.run(TestNG.java:1031)
at org.testng.remote.AbstractRemoteTestNG.run(AbstractRemoteTestNG.java:115)
at org.testng.remote.RemoteTestNG.initAndRun(RemoteTestNG.java:251)
at org.testng.remote.RemoteTestNG.main(RemoteTestNG.java:77)
]]>
    </error>
  </testcase> <!-- TestInsert_NullHoTen_Fail -->
  <system-out/>
  <testcase classname="DAO_Test.HoaDonDAO_Test" name="TestUpdate_NullNgayTao_Fail" time="0.081">
    <error message="
Method HoaDonDAO_Test.TestUpdate_NullNgayTao_Fail()[pri:0, instance:DAO_Test.HoaDonDAO_Test@6ab778a] should have thrown an exception of type class com.microsoft.sqlserver.jdbc.SQLServerException" type="org.testng.TestException">
      <![CDATA[org.testng.TestException: 
Method HoaDonDAO_Test.TestUpdate_NullNgayTao_Fail()[pri:0, instance:DAO_Test.HoaDonDAO_Test@6ab778a] should have thrown an exception of type class com.microsoft.sqlserver.jdbc.SQLServerException
at org.testng.internal.ExpectedExceptionsHolder.noException(ExpectedExceptionsHolder.java:82)
at org.testng.internal.TestInvoker.considerExceptions(TestInvoker.java:749)
at org.testng.internal.TestInvoker.invokeMethod(TestInvoker.java:634)
at org.testng.internal.TestInvoker.invokeTestMethod(TestInvoker.java:173)
at org.testng.internal.MethodRunner.runInSequence(MethodRunner.java:46)
at org.testng.internal.TestInvoker$MethodInvocationAgent.invoke(TestInvoker.java:824)
at org.testng.internal.TestInvoker.invokeTestMethods(TestInvoker.java:146)
at org.testng.internal.TestMethodWorker.invokeTestMethods(TestMethodWorker.java:146)
at org.testng.internal.TestMethodWorker.run(TestMethodWorker.java:128)
at java.base/java.util.ArrayList.forEach(ArrayList.java:1511)
at org.testng.TestRunner.privateRun(TestRunner.java:794)
at org.testng.TestRunner.run(TestRunner.java:596)
at org.testng.SuiteRunner.runTest(SuiteRunner.java:377)
at org.testng.SuiteRunner.runSequentially(SuiteRunner.java:371)
at org.testng.SuiteRunner.privateRun(SuiteRunner.java:332)
at org.testng.SuiteRunner.run(SuiteRunner.java:276)
at org.testng.SuiteRunnerWorker.runSuite(SuiteRunnerWorker.java:53)
at org.testng.SuiteRunnerWorker.run(SuiteRunnerWorker.java:96)
at org.testng.TestNG.runSuitesSequentially(TestNG.java:1212)
at org.testng.TestNG.runSuitesLocally(TestNG.java:1134)
at org.testng.TestNG.runSuites(TestNG.java:1063)
at org.testng.TestNG.run(TestNG.java:1031)
at org.testng.remote.AbstractRemoteTestNG.run(AbstractRemoteTestNG.java:115)
at org.testng.remote.RemoteTestNG.initAndRun(RemoteTestNG.java:251)
at org.testng.remote.RemoteTestNG.main(RemoteTestNG.java:77)
]]>
    </error>
  </testcase> <!-- TestUpdate_NullNgayTao_Fail -->
  <system-out/>
  <testcase classname="DAO_Test.HoaDonDAO_Test" name="TestSelecte_All_Pass" time="0.031"/>
  <system-out/>
  <testcase classname="DAO_Test.HoaDonDAO_Test" name="TestDanhSachHoaDon_Pass" time="0.056"/>
  <system-out/>
  <testcase classname="DAO_Test.HoaDonDAO_Test" name="TestInsert_NullDate_Fail" time="0.089">
    <error message="
Method HoaDonDAO_Test.TestInsert_NullDate_Fail()[pri:0, instance:DAO_Test.HoaDonDAO_Test@6ab778a] should have thrown an exception of type class com.microsoft.sqlserver.jdbc.SQLServerException" type="org.testng.TestException">
      <![CDATA[org.testng.TestException: 
Method HoaDonDAO_Test.TestInsert_NullDate_Fail()[pri:0, instance:DAO_Test.HoaDonDAO_Test@6ab778a] should have thrown an exception of type class com.microsoft.sqlserver.jdbc.SQLServerException
at org.testng.internal.ExpectedExceptionsHolder.noException(ExpectedExceptionsHolder.java:82)
at org.testng.internal.TestInvoker.considerExceptions(TestInvoker.java:749)
at org.testng.internal.TestInvoker.invokeMethod(TestInvoker.java:634)
at org.testng.internal.TestInvoker.invokeTestMethod(TestInvoker.java:173)
at org.testng.internal.MethodRunner.runInSequence(MethodRunner.java:46)
at org.testng.internal.TestInvoker$MethodInvocationAgent.invoke(TestInvoker.java:824)
at org.testng.internal.TestInvoker.invokeTestMethods(TestInvoker.java:146)
at org.testng.internal.TestMethodWorker.invokeTestMethods(TestMethodWorker.java:146)
at org.testng.internal.TestMethodWorker.run(TestMethodWorker.java:128)
at java.base/java.util.ArrayList.forEach(ArrayList.java:1511)
at org.testng.TestRunner.privateRun(TestRunner.java:794)
at org.testng.TestRunner.run(TestRunner.java:596)
at org.testng.SuiteRunner.runTest(SuiteRunner.java:377)
at org.testng.SuiteRunner.runSequentially(SuiteRunner.java:371)
at org.testng.SuiteRunner.privateRun(SuiteRunner.java:332)
at org.testng.SuiteRunner.run(SuiteRunner.java:276)
at org.testng.SuiteRunnerWorker.runSuite(SuiteRunnerWorker.java:53)
at org.testng.SuiteRunnerWorker.run(SuiteRunnerWorker.java:96)
at org.testng.TestNG.runSuitesSequentially(TestNG.java:1212)
at org.testng.TestNG.runSuitesLocally(TestNG.java:1134)
at org.testng.TestNG.runSuites(TestNG.java:1063)
at org.testng.TestNG.run(TestNG.java:1031)
at org.testng.remote.AbstractRemoteTestNG.run(AbstractRemoteTestNG.java:115)
at org.testng.remote.RemoteTestNG.initAndRun(RemoteTestNG.java:251)
at org.testng.remote.RemoteTestNG.main(RemoteTestNG.java:77)
]]>
    </error>
  </testcase> <!-- TestInsert_NullDate_Fail -->
  <system-out/>
  <testcase classname="DAO_Test.HoaDonDAO_Test" name="TestSelecte_All_Fail" time="0.037">
    <error message="
Expected exception of type class com.microsoft.sqlserver.jdbc.SQLServerException but got java.lang.AssertionError: expected [null] but found [[Entity.HoaDon@1c32386d, Entity.HoaDon@6399551e, Entity.HoaDon@13d73fa, Entity.HoaDon@5023bb8b, Entity.HoaDon@5d5f10b2, Entity.HoaDon@74c79fa2, Entity.HoaDon@1e0f9063, Entity.HoaDon@53bd8fca, Entity.HoaDon@7642df8f]]" type="org.testng.TestException">
      <![CDATA[org.testng.TestException: 
Expected exception of type class com.microsoft.sqlserver.jdbc.SQLServerException but got java.lang.AssertionError: expected [null] but found [[Entity.HoaDon@1c32386d, Entity.HoaDon@6399551e, Entity.HoaDon@13d73fa, Entity.HoaDon@5023bb8b, Entity.HoaDon@5d5f10b2, Entity.HoaDon@74c79fa2, Entity.HoaDon@1e0f9063, Entity.HoaDon@53bd8fca, Entity.HoaDon@7642df8f]]
at org.testng.internal.ExpectedExceptionsHolder.wrongException(ExpectedExceptionsHolder.java:68)
at org.testng.internal.TestInvoker.considerExceptions(TestInvoker.java:739)
at org.testng.internal.TestInvoker.invokeMethod(TestInvoker.java:634)
at org.testng.internal.TestInvoker.invokeTestMethod(TestInvoker.java:173)
at org.testng.internal.MethodRunner.runInSequence(MethodRunner.java:46)
at org.testng.internal.TestInvoker$MethodInvocationAgent.invoke(TestInvoker.java:824)
at org.testng.internal.TestInvoker.invokeTestMethods(TestInvoker.java:146)
at org.testng.internal.TestMethodWorker.invokeTestMethods(TestMethodWorker.java:146)
at org.testng.internal.TestMethodWorker.run(TestMethodWorker.java:128)
at java.base/java.util.ArrayList.forEach(ArrayList.java:1511)
at org.testng.TestRunner.privateRun(TestRunner.java:794)
at org.testng.TestRunner.run(TestRunner.java:596)
at org.testng.SuiteRunner.runTest(SuiteRunner.java:377)
at org.testng.SuiteRunner.runSequentially(SuiteRunner.java:371)
at org.testng.SuiteRunner.privateRun(SuiteRunner.java:332)
at org.testng.SuiteRunner.run(SuiteRunner.java:276)
at org.testng.SuiteRunnerWorker.runSuite(SuiteRunnerWorker.java:53)
at org.testng.SuiteRunnerWorker.run(SuiteRunnerWorker.java:96)
at org.testng.TestNG.runSuitesSequentially(TestNG.java:1212)
at org.testng.TestNG.runSuitesLocally(TestNG.java:1134)
at org.testng.TestNG.runSuites(TestNG.java:1063)
at org.testng.TestNG.run(TestNG.java:1031)
at org.testng.remote.AbstractRemoteTestNG.run(AbstractRemoteTestNG.java:115)
at org.testng.remote.RemoteTestNG.initAndRun(RemoteTestNG.java:251)
at org.testng.remote.RemoteTestNG.main(RemoteTestNG.java:77)
Caused by: java.lang.AssertionError: expected [null] but found [[Entity.HoaDon@1c32386d, Entity.HoaDon@6399551e, Entity.HoaDon@13d73fa, Entity.HoaDon@5023bb8b, Entity.HoaDon@5d5f10b2, Entity.HoaDon@74c79fa2, Entity.HoaDon@1e0f9063, Entity.HoaDon@53bd8fca, Entity.HoaDon@7642df8f]]
at org.testng.Assert.fail(Assert.java:99)
at org.testng.Assert.failNotSame(Assert.java:1033)
at org.testng.Assert.assertNull(Assert.java:965)
at org.testng.Assert.assertNull(Assert.java:953)
at DAO_Test.HoaDonDAO_Test.TestSelecte_All_Fail(HoaDonDAO_Test.java:240)
at java.base/jdk.internal.reflect.DirectMethodHandleAccessor.invoke(DirectMethodHandleAccessor.java:104)
at java.base/java.lang.reflect.Method.invoke(Method.java:578)
at org.testng.internal.MethodInvocationHelper.invokeMethod(MethodInvocationHelper.java:133)
at org.testng.internal.TestInvoker.invokeMethod(TestInvoker.java:598)
... 22 more
]]>
    </error>
  </testcase> <!-- TestSelecte_All_Fail -->
  <system-out/>
  <testcase classname="DAO_Test.HoaDonDAO_Test" name="TestUpdate_NullTenKhachHang_Fail" time="0.070">
    <error message="
Method HoaDonDAO_Test.TestUpdate_NullTenKhachHang_Fail()[pri:0, instance:DAO_Test.HoaDonDAO_Test@6ab778a] should have thrown an exception of type class com.microsoft.sqlserver.jdbc.SQLServerException" type="org.testng.TestException">
      <![CDATA[org.testng.TestException: 
Method HoaDonDAO_Test.TestUpdate_NullTenKhachHang_Fail()[pri:0, instance:DAO_Test.HoaDonDAO_Test@6ab778a] should have thrown an exception of type class com.microsoft.sqlserver.jdbc.SQLServerException
at org.testng.internal.ExpectedExceptionsHolder.noException(ExpectedExceptionsHolder.java:82)
at org.testng.internal.TestInvoker.considerExceptions(TestInvoker.java:749)
at org.testng.internal.TestInvoker.invokeMethod(TestInvoker.java:634)
at org.testng.internal.TestInvoker.invokeTestMethod(TestInvoker.java:173)
at org.testng.internal.MethodRunner.runInSequence(MethodRunner.java:46)
at org.testng.internal.TestInvoker$MethodInvocationAgent.invoke(TestInvoker.java:824)
at org.testng.internal.TestInvoker.invokeTestMethods(TestInvoker.java:146)
at org.testng.internal.TestMethodWorker.invokeTestMethods(TestMethodWorker.java:146)
at org.testng.internal.TestMethodWorker.run(TestMethodWorker.java:128)
at java.base/java.util.ArrayList.forEach(ArrayList.java:1511)
at org.testng.TestRunner.privateRun(TestRunner.java:794)
at org.testng.TestRunner.run(TestRunner.java:596)
at org.testng.SuiteRunner.runTest(SuiteRunner.java:377)
at org.testng.SuiteRunner.runSequentially(SuiteRunner.java:371)
at org.testng.SuiteRunner.privateRun(SuiteRunner.java:332)
at org.testng.SuiteRunner.run(SuiteRunner.java:276)
at org.testng.SuiteRunnerWorker.runSuite(SuiteRunnerWorker.java:53)
at org.testng.SuiteRunnerWorker.run(SuiteRunnerWorker.java:96)
at org.testng.TestNG.runSuitesSequentially(TestNG.java:1212)
at org.testng.TestNG.runSuitesLocally(TestNG.java:1134)
at org.testng.TestNG.runSuites(TestNG.java:1063)
at org.testng.TestNG.run(TestNG.java:1031)
at org.testng.remote.AbstractRemoteTestNG.run(AbstractRemoteTestNG.java:115)
at org.testng.remote.RemoteTestNG.initAndRun(RemoteTestNG.java:251)
at org.testng.remote.RemoteTestNG.main(RemoteTestNG.java:77)
]]>
    </error>
  </testcase> <!-- TestUpdate_NullTenKhachHang_Fail -->
  <system-out/>
  <testcase classname="DAO_Test.HoaDonDAO_Test" name="TestInsert_NullMaNV_Fail" time="0.063">
    <error message="
Method HoaDonDAO_Test.TestInsert_NullMaNV_Fail()[pri:0, instance:DAO_Test.HoaDonDAO_Test@6ab778a] should have thrown an exception of type class com.microsoft.sqlserver.jdbc.SQLServerException" type="org.testng.TestException">
      <![CDATA[org.testng.TestException: 
Method HoaDonDAO_Test.TestInsert_NullMaNV_Fail()[pri:0, instance:DAO_Test.HoaDonDAO_Test@6ab778a] should have thrown an exception of type class com.microsoft.sqlserver.jdbc.SQLServerException
at org.testng.internal.ExpectedExceptionsHolder.noException(ExpectedExceptionsHolder.java:82)
at org.testng.internal.TestInvoker.considerExceptions(TestInvoker.java:749)
at org.testng.internal.TestInvoker.invokeMethod(TestInvoker.java:634)
at org.testng.internal.TestInvoker.invokeTestMethod(TestInvoker.java:173)
at org.testng.internal.MethodRunner.runInSequence(MethodRunner.java:46)
at org.testng.internal.TestInvoker$MethodInvocationAgent.invoke(TestInvoker.java:824)
at org.testng.internal.TestInvoker.invokeTestMethods(TestInvoker.java:146)
at org.testng.internal.TestMethodWorker.invokeTestMethods(TestMethodWorker.java:146)
at org.testng.internal.TestMethodWorker.run(TestMethodWorker.java:128)
at java.base/java.util.ArrayList.forEach(ArrayList.java:1511)
at org.testng.TestRunner.privateRun(TestRunner.java:794)
at org.testng.TestRunner.run(TestRunner.java:596)
at org.testng.SuiteRunner.runTest(SuiteRunner.java:377)
at org.testng.SuiteRunner.runSequentially(SuiteRunner.java:371)
at org.testng.SuiteRunner.privateRun(SuiteRunner.java:332)
at org.testng.SuiteRunner.run(SuiteRunner.java:276)
at org.testng.SuiteRunnerWorker.runSuite(SuiteRunnerWorker.java:53)
at org.testng.SuiteRunnerWorker.run(SuiteRunnerWorker.java:96)
at org.testng.TestNG.runSuitesSequentially(TestNG.java:1212)
at org.testng.TestNG.runSuitesLocally(TestNG.java:1134)
at org.testng.TestNG.runSuites(TestNG.java:1063)
at org.testng.TestNG.run(TestNG.java:1031)
at org.testng.remote.AbstractRemoteTestNG.run(AbstractRemoteTestNG.java:115)
at org.testng.remote.RemoteTestNG.initAndRun(RemoteTestNG.java:251)
at org.testng.remote.RemoteTestNG.main(RemoteTestNG.java:77)
]]>
    </error>
  </testcase> <!-- TestInsert_NullMaNV_Fail -->
  <system-out/>
  <testcase classname="DAO_Test.HoaDonDAO_Test" name="TestSelect_BySQL_Pass" time="0.034"/>
  <system-out/>
  <testcase classname="DAO_Test.HoaDonDAO_Test" name="TestUpdate_GhiChu_Pass" time="0.061"/>
  <system-out/>
  <testcase classname="DAO_Test.HoaDonDAO_Test" name="TestDelete_Fail" time="0.072">
    <error message="
Method HoaDonDAO_Test.TestDelete_Fail()[pri:0, instance:DAO_Test.HoaDonDAO_Test@6ab778a] should have thrown an exception of type class com.microsoft.sqlserver.jdbc.SQLServerException" type="org.testng.TestException">
      <![CDATA[org.testng.TestException: 
Method HoaDonDAO_Test.TestDelete_Fail()[pri:0, instance:DAO_Test.HoaDonDAO_Test@6ab778a] should have thrown an exception of type class com.microsoft.sqlserver.jdbc.SQLServerException
at org.testng.internal.ExpectedExceptionsHolder.noException(ExpectedExceptionsHolder.java:82)
at org.testng.internal.TestInvoker.considerExceptions(TestInvoker.java:749)
at org.testng.internal.TestInvoker.invokeMethod(TestInvoker.java:634)
at org.testng.internal.TestInvoker.invokeTestMethod(TestInvoker.java:173)
at org.testng.internal.MethodRunner.runInSequence(MethodRunner.java:46)
at org.testng.internal.TestInvoker$MethodInvocationAgent.invoke(TestInvoker.java:824)
at org.testng.internal.TestInvoker.invokeTestMethods(TestInvoker.java:146)
at org.testng.internal.TestMethodWorker.invokeTestMethods(TestMethodWorker.java:146)
at org.testng.internal.TestMethodWorker.run(TestMethodWorker.java:128)
at java.base/java.util.ArrayList.forEach(ArrayList.java:1511)
at org.testng.TestRunner.privateRun(TestRunner.java:794)
at org.testng.TestRunner.run(TestRunner.java:596)
at org.testng.SuiteRunner.runTest(SuiteRunner.java:377)
at org.testng.SuiteRunner.runSequentially(SuiteRunner.java:371)
at org.testng.SuiteRunner.privateRun(SuiteRunner.java:332)
at org.testng.SuiteRunner.run(SuiteRunner.java:276)
at org.testng.SuiteRunnerWorker.runSuite(SuiteRunnerWorker.java:53)
at org.testng.SuiteRunnerWorker.run(SuiteRunnerWorker.java:96)
at org.testng.TestNG.runSuitesSequentially(TestNG.java:1212)
at org.testng.TestNG.runSuitesLocally(TestNG.java:1134)
at org.testng.TestNG.runSuites(TestNG.java:1063)
at org.testng.TestNG.run(TestNG.java:1031)
at org.testng.remote.AbstractRemoteTestNG.run(AbstractRemoteTestNG.java:115)
at org.testng.remote.RemoteTestNG.initAndRun(RemoteTestNG.java:251)
at org.testng.remote.RemoteTestNG.main(RemoteTestNG.java:77)
]]>
    </error>
  </testcase> <!-- TestDelete_Fail -->
  <system-out/>
  <testcase classname="DAO_Test.HoaDonDAO_Test" name="TestUpdate_TenKH_Pass" time="0.040"/>
  <system-out/>
  <testcase classname="DAO_Test.HoaDonDAO_Test" name="TestDanhSachHoaDon_Fail" time="0.559">
    <error message="
Expected exception of type class com.microsoft.sqlserver.jdbc.SQLServerException but got java.lang.AssertionError: expected [null] but found [[[Ljava.lang.Object;@7803bfd, [Ljava.lang.Object;@42bc14c1, [Ljava.lang.Object;@531f4093, [Ljava.lang.Object;@62ef27a8, [Ljava.lang.Object;@6436a7db, [Ljava.lang.Object;@460ebd80, [Ljava.lang.Object;@6f3c660a, [Ljava.lang.Object;@74f5ce22]]" type="org.testng.TestException">
      <![CDATA[org.testng.TestException: 
Expected exception of type class com.microsoft.sqlserver.jdbc.SQLServerException but got java.lang.AssertionError: expected [null] but found [[[Ljava.lang.Object;@7803bfd, [Ljava.lang.Object;@42bc14c1, [Ljava.lang.Object;@531f4093, [Ljava.lang.Object;@62ef27a8, [Ljava.lang.Object;@6436a7db, [Ljava.lang.Object;@460ebd80, [Ljava.lang.Object;@6f3c660a, [Ljava.lang.Object;@74f5ce22]]
at org.testng.internal.ExpectedExceptionsHolder.wrongException(ExpectedExceptionsHolder.java:68)
at org.testng.internal.TestInvoker.considerExceptions(TestInvoker.java:739)
at org.testng.internal.TestInvoker.invokeMethod(TestInvoker.java:634)
at org.testng.internal.TestInvoker.invokeTestMethod(TestInvoker.java:173)
at org.testng.internal.MethodRunner.runInSequence(MethodRunner.java:46)
at org.testng.internal.TestInvoker$MethodInvocationAgent.invoke(TestInvoker.java:824)
at org.testng.internal.TestInvoker.invokeTestMethods(TestInvoker.java:146)
at org.testng.internal.TestMethodWorker.invokeTestMethods(TestMethodWorker.java:146)
at org.testng.internal.TestMethodWorker.run(TestMethodWorker.java:128)
at java.base/java.util.ArrayList.forEach(ArrayList.java:1511)
at org.testng.TestRunner.privateRun(TestRunner.java:794)
at org.testng.TestRunner.run(TestRunner.java:596)
at org.testng.SuiteRunner.runTest(SuiteRunner.java:377)
at org.testng.SuiteRunner.runSequentially(SuiteRunner.java:371)
at org.testng.SuiteRunner.privateRun(SuiteRunner.java:332)
at org.testng.SuiteRunner.run(SuiteRunner.java:276)
at org.testng.SuiteRunnerWorker.runSuite(SuiteRunnerWorker.java:53)
at org.testng.SuiteRunnerWorker.run(SuiteRunnerWorker.java:96)
at org.testng.TestNG.runSuitesSequentially(TestNG.java:1212)
at org.testng.TestNG.runSuitesLocally(TestNG.java:1134)
at org.testng.TestNG.runSuites(TestNG.java:1063)
at org.testng.TestNG.run(TestNG.java:1031)
at org.testng.remote.AbstractRemoteTestNG.run(AbstractRemoteTestNG.java:115)
at org.testng.remote.RemoteTestNG.initAndRun(RemoteTestNG.java:251)
at org.testng.remote.RemoteTestNG.main(RemoteTestNG.java:77)
Caused by: java.lang.AssertionError: expected [null] but found [[[Ljava.lang.Object;@7803bfd, [Ljava.lang.Object;@42bc14c1, [Ljava.lang.Object;@531f4093, [Ljava.lang.Object;@62ef27a8, [Ljava.lang.Object;@6436a7db, [Ljava.lang.Object;@460ebd80, [Ljava.lang.Object;@6f3c660a, [Ljava.lang.Object;@74f5ce22]]
at org.testng.Assert.fail(Assert.java:99)
at org.testng.Assert.failNotSame(Assert.java:1033)
at org.testng.Assert.assertNull(Assert.java:965)
at org.testng.Assert.assertNull(Assert.java:953)
at DAO_Test.HoaDonDAO_Test.TestDanhSachHoaDon_Fail(HoaDonDAO_Test.java:258)
at java.base/jdk.internal.reflect.DirectMethodHandleAccessor.invoke(DirectMethodHandleAccessor.java:104)
at java.base/java.lang.reflect.Method.invoke(Method.java:578)
at org.testng.internal.MethodInvocationHelper.invokeMethod(MethodInvocationHelper.java:133)
at org.testng.internal.TestInvoker.invokeMethod(TestInvoker.java:598)
... 22 more
]]>
    </error>
  </testcase> <!-- TestDanhSachHoaDon_Fail -->
  <system-out/>
  <testcase classname="DAO_Test.HoaDonDAO_Test" name="TestSelect_ByID_Pass" time="0.031">
    <failure message="expected object to not be null" type="java.lang.AssertionError">
      <![CDATA[java.lang.AssertionError: expected object to not be null
at org.testng.Assert.fail(Assert.java:99)
at org.testng.Assert.assertNotNull(Assert.java:942)
at org.testng.Assert.assertNotNull(Assert.java:926)
at DAO_Test.HoaDonDAO_Test.TestSelect_ByID_Pass(HoaDonDAO_Test.java:268)
at java.base/jdk.internal.reflect.DirectMethodHandleAccessor.invoke(DirectMethodHandleAccessor.java:104)
at java.base/java.lang.reflect.Method.invoke(Method.java:578)
at org.testng.internal.MethodInvocationHelper.invokeMethod(MethodInvocationHelper.java:133)
at org.testng.internal.TestInvoker.invokeMethod(TestInvoker.java:598)
at org.testng.internal.TestInvoker.invokeTestMethod(TestInvoker.java:173)
at org.testng.internal.MethodRunner.runInSequence(MethodRunner.java:46)
at org.testng.internal.TestInvoker$MethodInvocationAgent.invoke(TestInvoker.java:824)
at org.testng.internal.TestInvoker.invokeTestMethods(TestInvoker.java:146)
at org.testng.internal.TestMethodWorker.invokeTestMethods(TestMethodWorker.java:146)
at org.testng.internal.TestMethodWorker.run(TestMethodWorker.java:128)
at java.base/java.util.ArrayList.forEach(ArrayList.java:1511)
at org.testng.TestRunner.privateRun(TestRunner.java:794)
at org.testng.TestRunner.run(TestRunner.java:596)
at org.testng.SuiteRunner.runTest(SuiteRunner.java:377)
at org.testng.SuiteRunner.runSequentially(SuiteRunner.java:371)
at org.testng.SuiteRunner.privateRun(SuiteRunner.java:332)
at org.testng.SuiteRunner.run(SuiteRunner.java:276)
at org.testng.SuiteRunnerWorker.runSuite(SuiteRunnerWorker.java:53)
at org.testng.SuiteRunnerWorker.run(SuiteRunnerWorker.java:96)
at org.testng.TestNG.runSuitesSequentially(TestNG.java:1212)
at org.testng.TestNG.runSuitesLocally(TestNG.java:1134)
at org.testng.TestNG.runSuites(TestNG.java:1063)
at org.testng.TestNG.run(TestNG.java:1031)
at org.testng.remote.AbstractRemoteTestNG.run(AbstractRemoteTestNG.java:115)
at org.testng.remote.RemoteTestNG.initAndRun(RemoteTestNG.java:251)
at org.testng.remote.RemoteTestNG.main(RemoteTestNG.java:77)
]]>
    </failure>
  </testcase> <!-- TestSelect_ByID_Pass -->
  <system-out/>
</testsuite> <!-- DAO_Test.HoaDonDAO_Test -->
